Workbook

Sheet Plataformas Credito
A1: ID | B1: DC | C1: Proveedor | D1: Hostname | E1: Nombre DNS | F1: Dirección IP | G1: Ambiente | H1: Software MDW | I1: Aplicación | J1: Servicio de Negocio | K1: Estado | L1: Categoría | M1: Tipo | N1: Número de Serie | O1: Categoría S.O | P1: Familia S.O | Q1: Sistema operativo | R1: EOL (API) | S1: Update Disponible | U1: Obsolescencia SO | V1: Obsolescencia SW MDW y/o APP | W1: Obsolescencia HW | X1: Obsolescencia BBDD | Y1: Grado de Obsolescencia Global | Z1: Proyecto Obsolescencia | AA1: Fecha Compromiso | AB1: G. Responsable Plan | AC1: Líder | AD1: Expuesto | AE1: Antivirus | AF1: DSVO | AG1: Central Desktop | AH1: Sysmon | AI1: Usuario Negocio | AJ1: Líder Gerencia | AK1: Indicador Proyecto | AM1: Cr | AN1: BIA
A2: 16 | B2: GCVE | C2: GCVE | D2: ADFS-TAKAHE-PRO | E2: takahe | F2: 10.23.4.228 | G2: Producción | H2: Sin Software MDW | I2: ADFS | J2: ADFS | K2: Encendido | L2: Virtual | M2: Máquina Virtual VmWare | N2: No aplica | O2: Microsoft Windows | P2: Microsoft Windows Server 2012 | Q2: Microsoft Windows Server 2012 (64-bit) | R2: =verificarVersionOS(Q2) -> #NAME? | S2: =IFERROR( IF(ISNUMBER(FIND("Soporte hasta: ", R2)), IF(VALUE(MID(R2,16,10))<TODAY(),"🟥 Obsoleto", IF(YEAR(VALUE(MID(R2,16,10)))=YEAR(TODAY()),"Actualizaciones disponibles", IF(YEAR(VALUE(MID(R2,16,10)))-YEAR(TODAY())=1,"Actualizaciones disponibles", IF(YEAR(VALUE(MID(R2,16,10)))-YEAR(TODAY())=2,"Actualizaciones disponibles", "Actualizaciones disponibles" ) ) ) ), "⛔ Sin datos" ), "⛔ Error en fecha" ) -> ⛔ Sin datos | T2: =IF(OR(S2 = "🟥 Obsoleto",S2 = "⛔ Sin datos"), "Ya no cuenta con actualizaciones", IFERROR( CONCATENATE( "E" & IFERROR(CHOOSE(MATCH(INDEX(ControlMensual!H:H, MATCH(F2, ControlMensual!B:B, 0)), {"ok";"no";"pendiente"}, 0),"✅","❌","🕓"), "⛔") & " ", "F" & IFERROR(CHOOSE(MATCH(INDEX(ControlMensual!I:I, MATCH(F2, ControlMensual!B:B, 0)), {"ok";"no";"pendiente"}, 0),"✅","❌","🕓"), "⛔") & " ", "M" & IFERROR(CHOOSE(MATCH(INDEX(ControlMensual!J:J, MATCH(F2, ControlMensual!B:B, 0)), {"ok";"no";"pendiente"}, 0),"✅","❌","🕓"), "⛔") & " ", "A" & IFERROR(CHOOSE(MATCH(INDEX(ControlMensual!K:K, MATCH(F2, ControlMensual!B:B, 0)), {"ok";"no";"pendiente"}, 0),"✅","❌","🕓"), "⛔") & " ", "M" & IFERROR(CHOOSE(MATCH(INDEX(ControlMensual!L:L, MATCH(F2, ControlMensual!B:B, 0)), {"ok";"no";"pendiente"}, 0),"✅","❌","🕓"), "⛔") & " ", "J" & IFERROR(CHOOSE(MATCH(INDEX(ControlMensual!M:M, MATCH(F2, ControlMensual!B:B, 0)), {"ok";"no";"pendiente"}, 0),"✅","❌","🕓"), "⛔") & " ", "J" & IFERROR(CHOOSE(MATCH(INDEX(ControlMensual!N:N, MATCH(F2, ControlMensual!B:B, 0)), {"ok";"no";"pendiente"}, 0),"✅","❌","🕓"), "⛔") & " ", "A" & IFERROR(CHOOSE(MATCH(INDEX(ControlMensual!O:O, MATCH(F2, ControlMensual!B:B, 0)), {"ok";"no";"pendiente"}, 0),"✅","❌","🕓"), "⛔") & " ", "S" & IFERROR(CHOOSE(MATCH(INDEX(ControlMensual!P:P, MATCH(F2, ControlMensual!B:B, 0)), {"ok";"no";"pendiente"}, 0),"✅","❌","🕓"), "⛔") & " ", "O" & IFERROR(CHOOSE(MATCH(INDEX(ControlMensual!Q:Q, MATCH(F2, ControlMensual!B:B, 0)), {"ok";"no";"pendiente"}, 0),"✅","❌","🕓"), "⛔") & " ", "N" & IFERROR(CHOOSE(MATCH(INDEX(ControlMensual!R:R, MATCH(F2, ControlMensual!B:B, 0)), {"ok";"no";"pendiente"}, 0),"✅","❌","🕓"), "⛔") & " ", "D" & IFERROR(CHOOSE(MATCH(INDEX(ControlMensual!S:S, MATCH(F2, ControlMensual!B:B, 0)), {"ok";"no";"pendiente"}, 0),"✅","❌","🕓"), "⛔") ) ,"") ) -> Ya no cuenta con actualizaciones | U2: Si | V2: No | W2: No | X2: No Aplica | Y2: =COUNTIF(U2:X2,"Si")/(COUNTIF(U2:X2,"Si")+COUNTIF(U2:X2,"No")) -> 0.33333333 | Z2: Migración FICO | AA2: 45930 | AB2: Sistemas Financieros | AC2: Claudia León | AD2: No | AE2: =VLOOKUP(E2,Falcon!B$2:C$558,2,FALSE) -> #REF! | AF2: =VLOOKUP(E2,VisionOne!B$2:C$229,2,FALSE) -> #REF! | AG2: =VLOOKUP(E2,Central!B$2:C$217,2,FALSE) -> #REF! | AH2: Si | AJ2: Patricio Alegría | AK2: Si | AL2: x | AM2: =VLOOKUP(D2,'Copia de vInfo 2'!A:A,1,FALSE) -> #REF!
A3: 19 | B3: GCVE | C3: GCVE | D3: RIESGO-BACHELOR-PRO | E3: BACHELOR | F3: 10.23.2.119 | G3: Producción | H3: Sin Software MDW | I3: Análisis Datos Riesgo | J3: Análisis Datos Riesgo | K3: Encendido | L3: Virtual | M3: Máquina Virtual VmWare | N3: No aplica | O3: Microsoft Windows | P3: Microsoft Windows Server 2008 | Q3: Microsoft Windows Server 2008 R2 (64-bit) | R3: =verificarVersionOS(Q3) -> #NAME? | S3: =IFERROR( IF(ISNUMBER(FIND("Soporte hasta: ", R3)), IF(VALUE(MID(R3,16,10))<TODAY(),"🟥 Obsoleto", IF(YEAR(VALUE(MID(R3,16,10)))=YEAR(TODAY()),"Actualizaciones disponibles", IF(YEAR(VALUE(MID(R3,16,10)))-YEAR(TODAY())=1,"Actualizaciones disponibles", IF(YEAR(VALUE(MID(R3,16,10)))-YEAR(TODAY())=2,"Actualizaciones disponibles", "Actualizaciones disponibles" ) ) ) ), "⛔ Sin datos" ), "⛔ Error en fecha" ) -> ⛔ Sin datos | T3: =IF(OR(S3 = "🟥 Obsoleto",S3 = "⛔ Sin datos"), "Ya no cuenta con actualizaciones", IFERROR( CONCATENATE( "E" & IFERROR(CHOOSE(MATCH(INDEX(ControlMensual!H:H, MATCH(F3, ControlMensual!B:B, 0)), {"ok";"no";"pendiente"}, 0),"✅","❌","🕓"), "⛔") & " ", "F" & IFERROR(CHOOSE(MATCH(INDEX(ControlMensual!I:I, MATCH(F3, ControlMensual!B:B, 0)), {"ok";"no";"pendiente"}, 0),"✅","❌","🕓"), "⛔") & " ", "M" & IFERROR(CHOOSE(MATCH(INDEX(ControlMensual!J:J, MATCH(F3, ControlMensual!B:B, 0)), {"ok";"no";"pendiente"}, 0),"✅","❌","🕓"), "⛔") & " ", "A" & IFERROR(CHOOSE(MATCH(INDEX(ControlMensual!K:K, MATCH(F3, ControlMensual!B:B, 0)), {"ok";"no";"pendiente"}, 0),"✅","❌","🕓"), "⛔") & " ", "M" & IFERROR(CHOOSE(MATCH(INDEX(ControlMensual!L:L, MATCH(F3, ControlMensual!B:B, 0)), {"ok";"no";"pendiente"}, 0),"✅","❌","🕓"), "⛔") & " ", "J" & IFERROR(CHOOSE(MATCH(INDEX(ControlMensual!M:M, MATCH(F3, ControlMensual!B:B, 0)), {"ok";"no";"pendiente"}, 0),"✅","❌","🕓"), "⛔") & " ", "J" & IFERROR(CHOOSE(MATCH(INDEX(ControlMensual!N:N, MATCH(F3, ControlMensual!B:B, 0)), {"ok";"no";"pendiente"}, 0),"✅","❌","🕓"), "⛔") & " ", "A" & IFERROR(CHOOSE(MATCH(INDEX(ControlMensual!O:O, MATCH(F3, ControlMensual!B:B, 0)), {"ok";"no";"pendiente"}, 0),"✅","❌","🕓"), "⛔") & " ", "S" & IFERROR(CHOOSE(MATCH(INDEX(ControlMensual!P:P, MATCH(F3, ControlMensual!B:B, 0)), {"ok";"no";"pendiente"}, 0),"✅","❌","🕓"), "⛔") & " ", "O" & IFERROR(CHOOSE(MATCH(INDEX(ControlMensual!Q:Q, MATCH(F3, ControlMensual!B:B, 0)), {"ok";"no";"pendiente"}, 0),"✅","❌","🕓"), "⛔") & " ", "N" & IFERROR(CHOOSE(MATCH(INDEX(ControlMensual!R:R, MATCH(F3, ControlMensual!B:B, 0)), {"ok";"no";"pendiente"}, 0),"✅","❌","🕓"), "⛔") & " ", "D" & IFERROR(CHOOSE(MATCH(INDEX(ControlMensual!S:S, MATCH(F3, ControlMensual!B:B, 0)), {"ok";"no";"pendiente"}, 0),"✅","❌","🕓"), "⛔") ) ,"") ) -> Ya no cuenta con actualizaciones | U3: Si | V3: Si | W3: No | X3: No aplica | Y3: =COUNTIF(U3:X3,"Si")/(COUNTIF(U3:X3,"Si")+COUNTIF(U3:X3,"No")) -> 0.66666667 | Z3: Sin Proyecto | AA3: Sin Fecha | AB3: Riesgos | AC3: Sin Asignación | AD3: No | AE3: =VLOOKUP(E3,Falcon!B$2:C$558,2,FALSE) -> #REF! | AF3: =VLOOKUP(E3,VisionOne!B$2:C$229,2,FALSE) -> #REF! | AG3: =VLOOKUP(E3,Central!B$2:C$217,2,FALSE) -> #REF! | AH3: No | AJ3: Cristian Rosales | AK3: No | AM3: =VLOOKUP(D3,'Copia de vInfo 2'!A:A,1,FALSE) -> #REF!
A4: 21 | B4: GCVE | C4: GCVE | D4: RIESGO-COPIAPO-PRO | E4: COPIAPO | F4: 10.23.2.158 | G4: Producción | H4: Sin Software MDW | I4: Análisis Datos Riesgo | J4: Análisis Datos Riesgo | K4: Encendido | L4: Virtual | M4: Máquina Virtual VmWare | N4: No aplica | O4: Microsoft Windows | P4: Microsoft Windows Server 2008 | Q4: Microsoft Windows Server 2008 R2 (64-bit) | R4: =verificarVersionOS(Q4) -> #NAME? | S4: =IFERROR( IF(ISNUMBER(FIND("Soporte hasta: ", R4)), IF(VALUE(MID(R4,16,10))<TODAY(),"🟥 Obsoleto", IF(YEAR(VALUE(MID(R4,16,10)))=YEAR(TODAY()),"Actualizaciones disponibles", IF(YEAR(VALUE(MID(R4,16,10)))-YEAR(TODAY())=1,"Actualizaciones disponibles", IF(YEAR(VALUE(MID(R4,16,10)))-YEAR(TODAY())=2,"Actualizaciones disponibles", "Actualizaciones disponibles" ) ) ) ), "⛔ Sin datos" ), "⛔ Error en fecha" ) -> ⛔ Sin datos | T4: =IF(OR(S4 = "🟥 Obsoleto",S4 = "⛔ Sin datos"), "Ya no cuenta con actualizaciones", IFERROR( CONCATENATE( "E" & IFERROR(CHOOSE(MATCH(INDEX(ControlMensual!H:H, MATCH(F4, ControlMensual!B:B, 0)), {"ok";"no";"pendiente"}, 0),"✅","❌","🕓"), "⛔") & " ", "F" & IFERROR(CHOOSE(MATCH(INDEX(ControlMensual!I:I, MATCH(F4, ControlMensual!B:B, 0)), {"ok";"no";"pendiente"}, 0),"✅","❌","🕓"), "⛔") & " ", "M" & IFERROR(CHOOSE(MATCH(INDEX(ControlMensual!J:J, MATCH(F4, ControlMensual!B:B, 0)), {"ok";"no";"pendiente"}, 0),"✅","❌","🕓"), "⛔") & " ", "A" & IFERROR(CHOOSE(MATCH(INDEX(ControlMensual!K:K, MATCH(F4, ControlMensual!B:B, 0)), {"ok";"no";"pendiente"}, 0),"✅","❌","🕓"), "⛔") & " ", "M" & IFERROR(CHOOSE(MATCH(INDEX(ControlMensual!L:L, MATCH(F4, ControlMensual!B:B, 0)), {"ok";"no";"pendiente"}, 0),"✅","❌","🕓"), "⛔") & " ", "J" & IFERROR(CHOOSE(MATCH(INDEX(ControlMensual!M:M, MATCH(F4, ControlMensual!B:B, 0)), {"ok";"no";"pendiente"}, 0),"✅","❌","🕓"), "⛔") & " ", "J" & IFERROR(CHOOSE(MATCH(INDEX(ControlMensual!N:N, MATCH(F4, ControlMensual!B:B, 0)), {"ok";"no";"pendiente"}, 0),"✅","❌","🕓"), "⛔") & " ", "A" & IFERROR(CHOOSE(MATCH(INDEX(ControlMensual!O:O, MATCH(F4, ControlMensual!B:B, 0)), {"ok";"no";"pendiente"}, 0),"✅","❌","🕓"), "⛔") & " ", "S" & IFERROR(CHOOSE(MATCH(INDEX(ControlMensual!P:P, MATCH(F4, ControlMensual!B:B, 0)), {"ok";"no";"pendiente"}, 0),"✅","❌","🕓"), "⛔") & " ", "O" & IFERROR(CHOOSE(MATCH(INDEX(ControlMensual!Q:Q, MATCH(F4, ControlMensual!B:B, 0)), {"ok";"no";"pendiente"}, 0),"✅","❌","🕓"), "⛔") & " ", "N" & IFERROR(CHOOSE(MATCH(INDEX(ControlMensual!R:R, MATCH(F4, ControlMensual!B:B, 0)), {"ok";"no";"pendiente"}, 0),"✅","❌","🕓"), "⛔") & " ", "D" & IFERROR(CHOOSE(MATCH(INDEX(ControlMensual!S:S, MATCH(F4, ControlMensual!B:B, 0)), {"ok";"no";"pendiente"}, 0),"✅","❌","🕓"), "⛔") ) ,"") ) -> Ya no cuenta con actualizaciones | U4: Si | V4: Si | W4: No | X4: Si | Y4: =COUNTIF(U4:X4,"Si")/(COUNTIF(U4:X4,"Si")+COUNTIF(U4:X4,"No")) -> 0.75 | Z4: Sin Proyecto | AA4: Sin Fecha | AB4: Riesgos | AC4: Santiago Galleguillos | AD4: No | AE4: =VLOOKUP(E4,Falcon!B$2:C$558,2,FALSE) -> #REF! | AF4: =VLOOKUP(E4,VisionOne!B$2:C$229,2,FALSE) -> #REF! | AG4: =VLOOKUP(E4,Central!B$2:C$217,2,FALSE) -> #REF! | AH4: No | AI4: Santiago Galleguillos | AJ4: Cristian Rosales | AK4: No | AM4: =VLOOKUP(D4,'Copia de vInfo 2'!A:A,1,FALSE) -> #REF!
A5: 47 | B5: GCVE | C5: GCVE | D5: CREDIGI-COCHONS-DEV | E5: cochons | F5: 10.23.2.213 | G5: Desarrollo | H5: Sin Software MDW | I5: Crédito Digital | J5: Crédito Digital | K5: Encendido | L5: Virtual | M5: Máquina Virtual VmWare | N5: No aplica | O5: Linux | P5: Centos 4/5/6/7 | Q5: CentOS 7 (64-bit) | R5: =verificarVersionOS(Q5) -> #NAME? | S5: =IFERROR( IF(ISNUMBER(FIND("Soporte hasta: ", R5)), IF(VALUE(MID(R5,16,10))<TODAY(),"🟥 Obsoleto", IF(YEAR(VALUE(MID(R5,16,10)))=YEAR(TODAY()),"Actualizaciones disponibles", IF(YEAR(VALUE(MID(R5,16,10)))-YEAR(TODAY())=1,"Actualizaciones disponibles", IF(YEAR(VALUE(MID(R5,16,10)))-YEAR(TODAY())=2,"Actualizaciones disponibles", "Actualizaciones disponibles" ) ) ) ), "⛔ Sin datos" ), "⛔ Error en fecha" ) -> ⛔ Sin datos | T5: =IF(OR(S5 = "🟥 Obsoleto",S5 = "⛔ Sin datos"), "Ya no cuenta con actualizaciones", IFERROR( CONCATENATE( "E" & IFERROR(CHOOSE(MATCH(INDEX(ControlMensual!H:H, MATCH(F5, ControlMensual!B:B, 0)), {"ok";"no";"pendiente"}, 0),"✅","❌","🕓"), "⛔") & " ", "F" & IFERROR(CHOOSE(MATCH(INDEX(ControlMensual!I:I, MATCH(F5, ControlMensual!B:B, 0)), {"ok";"no";"pendiente"}, 0),"✅","❌","🕓"), "⛔") & " ", "M" & IFERROR(CHOOSE(MATCH(INDEX(ControlMensual!J:J, MATCH(F5, ControlMensual!B:B, 0)), {"ok";"no";"pendiente"}, 0),"✅","❌","🕓"), "⛔") & " ", "A" & IFERROR(CHOOSE(MATCH(INDEX(ControlMensual!K:K, MATCH(F5, ControlMensual!B:B, 0)), {"ok";"no";"pendiente"}, 0),"✅","❌","🕓"), "⛔") & " ", "M" & IFERROR(CHOOSE(MATCH(INDEX(ControlMensual!L:L, MATCH(F5, ControlMensual!B:B, 0)), {"ok";"no";"pendiente"}, 0),"✅","❌","🕓"), "⛔") & " ", "J" & IFERROR(CHOOSE(MATCH(INDEX(ControlMensual!M:M, MATCH(F5, ControlMensual!B:B, 0)), {"ok";"no";"pendiente"}, 0),"✅","❌","🕓"), "⛔") & " ", "J" & IFERROR(CHOOSE(MATCH(INDEX(ControlMensual!N:N, MATCH(F5, ControlMensual!B:B, 0)), {"ok";"no";"pendiente"}, 0),"✅","❌","🕓"), "⛔") & " ", "A" & IFERROR(CHOOSE(MATCH(INDEX(ControlMensual!O:O, MATCH(F5, ControlMensual!B:B, 0)), {"ok";"no";"pendiente"}, 0),"✅","❌","🕓"), "⛔") & " ", "S" & IFERROR(CHOOSE(MATCH(INDEX(ControlMensual!P:P, MATCH(F5, ControlMensual!B:B, 0)), {"ok";"no";"pendiente"}, 0),"✅","❌","🕓"), "⛔") & " ", "O" & IFERROR(CHOOSE(MATCH(INDEX(ControlMensual!Q:Q, MATCH(F5, ControlMensual!B:B, 0)), {"ok";"no";"pendiente"}, 0),"✅","❌","🕓"), "⛔") & " ", "N" & IFERROR(CHOOSE(MATCH(INDEX(ControlMensual!R:R, MATCH(F5, ControlMensual!B:B, 0)), {"ok";"no";"pendiente"}, 0),"✅","❌","🕓"), "⛔") & " ", "D" & IFERROR(CHOOSE(MATCH(INDEX(ControlMensual!S:S, MATCH(F5, ControlMensual!B:B, 0)), {"ok";"no";"pendiente"}, 0),"✅","❌","🕓"), "⛔") ) ,"") ) -> Ya no cuenta con actualizaciones | U5: Si | V5: Si | W5: No | X5: No Aplica | Y5: =COUNTIF(U5:X5,"Si")/(COUNTIF(U5:X5,"Si")+COUNTIF(U5:X5,"No")) -> 0.66666667 | Z5: Sin Proyecto | AA5: Sin Fecha | AB5: Sistemas Financieros | AC5: Sin Asignación | AD5: No | AE5: =VLOOKUP(E6,Falcon!B$2:C$558,2,FALSE) -> #REF! | AF5: =VLOOKUP(E5,VisionOne!B$2:C$229,2,FALSE) -> #REF! | AG5: =VLOOKUP(E5,Central!B$2:C$217,2,FALSE) -> #REF! | AH5: No | AJ5: Patricio Alegría | AK5: No
A6: 48 | B6: GCVE | C6: GCVE | D6: CREDIGI-SANPAUL-DEV | E6: sanpaul | F6: 10.23.2.212 | G6: Desarrollo | H6: Sin Software MDW | I6: Crédito Digital | J6: Crédito Digital | K6: Encendido | L6: Virtual | M6: Máquina Virtual VmWare | N6: No aplica | O6: Linux | P6: Centos 4/5/6/7 | Q6: CentOS 7 (64-bit) | R6: =verificarVersionOS(Q6) -> #NAME? | S6: =IFERROR( IF(ISNUMBER(FIND("Soporte hasta: ", R6)), IF(VALUE(MID(R6,16,10))<TODAY(),"🟥 Obsoleto", IF(YEAR(VALUE(MID(R6,16,10)))=YEAR(TODAY()),"Actualizaciones disponibles", IF(YEAR(VALUE(MID(R6,16,10)))-YEAR(TODAY())=1,"Actualizaciones disponibles", IF(YEAR(VALUE(MID(R6,16,10)))-YEAR(TODAY())=2,"Actualizaciones disponibles", "Actualizaciones disponibles" ) ) ) ), "⛔ Sin datos" ), "⛔ Error en fecha" ) -> ⛔ Sin datos | T6: =IF(OR(S6 = "🟥 Obsoleto",S6 = "⛔ Sin datos"), "Ya no cuenta con actualizaciones", IFERROR( CONCATENATE( "E" & IFERROR(CHOOSE(MATCH(INDEX(ControlMensual!H:H, MATCH(F6, ControlMensual!B:B, 0)), {"ok";"no";"pendiente"}, 0),"✅","❌","🕓"), "⛔") & " ", "F" & IFERROR(CHOOSE(MATCH(INDEX(ControlMensual!I:I, MATCH(F6, ControlMensual!B:B, 0)), {"ok";"no";"pendiente"}, 0),"✅","❌","🕓"), "⛔") & " ", "M" & IFERROR(CHOOSE(MATCH(INDEX(ControlMensual!J:J, MATCH(F6, ControlMensual!B:B, 0)), {"ok";"no";"pendiente"}, 0),"✅","❌","🕓"), "⛔") & " ", "A" & IFERROR(CHOOSE(MATCH(INDEX(ControlMensual!K:K, MATCH(F6, ControlMensual!B:B, 0)), {"ok";"no";"pendiente"}, 0),"✅","❌","🕓"), "⛔") & " ", "M" & IFERROR(CHOOSE(MATCH(INDEX(ControlMensual!L:L, MATCH(F6, ControlMensual!B:B, 0)), {"ok";"no";"pendiente"}, 0),"✅","❌","🕓"), "⛔") & " ", "J" & IFERROR(CHOOSE(MATCH(INDEX(ControlMensual!M:M, MATCH(F6, ControlMensual!B:B, 0)), {"ok";"no";"pendiente"}, 0),"✅","❌","🕓"), "⛔") & " ", "J" & IFERROR(CHOOSE(MATCH(INDEX(ControlMensual!N:N, MATCH(F6, ControlMensual!B:B, 0)), {"ok";"no";"pendiente"}, 0),"✅","❌","🕓"), "⛔") & " ", "A" & IFERROR(CHOOSE(MATCH(INDEX(ControlMensual!O:O, MATCH(F6, ControlMensual!B:B, 0)), {"ok";"no";"pendiente"}, 0),"✅","❌","🕓"), "⛔") & " ", "S" & IFERROR(CHOOSE(MATCH(INDEX(ControlMensual!P:P, MATCH(F6, ControlMensual!B:B, 0)), {"ok";"no";"pendiente"}, 0),"✅","❌","🕓"), "⛔") & " ", "O" & IFERROR(CHOOSE(MATCH(INDEX(ControlMensual!Q:Q, MATCH(F6, ControlMensual!B:B, 0)), {"ok";"no";"pendiente"}, 0),"✅","❌","🕓"), "⛔") & " ", "N" & IFERROR(CHOOSE(MATCH(INDEX(ControlMensual!R:R, MATCH(F6, ControlMensual!B:B, 0)), {"ok";"no";"pendiente"}, 0),"✅","❌","🕓"), "⛔") & " ", "D" & IFERROR(CHOOSE(MATCH(INDEX(ControlMensual!S:S, MATCH(F6, ControlMensual!B:B, 0)), {"ok";"no";"pendiente"}, 0),"✅","❌","🕓"), "⛔") ) ,"") ) -> Ya no cuenta con actualizaciones | U6: Si | V6: Si | W6: No | X6: No Aplica | Y6: =COUNTIF(U6:X6,"Si")/(COUNTIF(U6:X6,"Si")+COUNTIF(U6:X6,"No")) -> 0.66666667 | Z6: Sin Proyecto | AA6: Sin Fecha | AB6: Sistemas Financieros | AC6: Sin Asignación | AD6: No | AF6: =VLOOKUP(E6,VisionOne!B$2:C$229,2,FALSE) -> #REF! | AG6: =VLOOKUP(E6,Central!B$2:C$217,2,FALSE) -> #REF! | AH6: No | AJ6: Patricio Alegría | AK6: No | AM6: =VLOOKUP(D6,'Copia de vInfo 2'!A:A,1,FALSE) -> #REF!
A7: 172 | B7: Alonso Ovalle | C7: Alonso Ovalle | D7: DESA-WEBLOGIC-BORALE | E7: borale | F7: 10.23.4.98 | G7: Desarrollo | H7: =VLOOKUP(D7,'Inventario Plataformas OLD 260325'!I:Q,2,FALSE) -> #REF! | I7: Weblogic Transversal | J7: Servicios Transversales MDW | K7: Encendido | L7: Virtual | M7: Máquina Virtual VmWare | N7: No aplica | O7: Linux | P7: Red Hat Enterprise Linux 6 | Q7: Red Hat Enterprise Linux 6 (64-bit) | R7: =verificarVersionOS(Q7) -> #NAME? | S7: =IFERROR( IF(ISNUMBER(FIND("Soporte hasta: ", R7)), IF(VALUE(MID(R7,16,10))<TODAY(),"🟥 Obsoleto", IF(YEAR(VALUE(MID(R7,16,10)))=YEAR(TODAY()),"Actualizaciones disponibles", IF(YEAR(VALUE(MID(R7,16,10)))-YEAR(TODAY())=1,"Actualizaciones disponibles", IF(YEAR(VALUE(MID(R7,16,10)))-YEAR(TODAY())=2,"Actualizaciones disponibles", "Actualizaciones disponibles" ) ) ) ), "⛔ Sin datos" ), "⛔ Error en fecha" ) -> ⛔ Sin datos | T7: =IF(OR(S7 = "🟥 Obsoleto",S7 = "⛔ Sin datos"), "Ya no cuenta con actualizaciones", IFERROR( CONCATENATE( "E" & IFERROR(CHOOSE(MATCH(INDEX(ControlMensual!H:H, MATCH(F7, ControlMensual!B:B, 0)), {"ok";"no";"pendiente"}, 0),"✅","❌","🕓"), "⛔") & " ", "F" & IFERROR(CHOOSE(MATCH(INDEX(ControlMensual!I:I, MATCH(F7, ControlMensual!B:B, 0)), {"ok";"no";"pendiente"}, 0),"✅","❌","🕓"), "⛔") & " ", "M" & IFERROR(CHOOSE(MATCH(INDEX(ControlMensual!J:J, MATCH(F7, ControlMensual!B:B, 0)), {"ok";"no";"pendiente"}, 0),"✅","❌","🕓"), "⛔") & " ", "A" & IFERROR(CHOOSE(MATCH(INDEX(ControlMensual!K:K, MATCH(F7, ControlMensual!B:B, 0)), {"ok";"no";"pendiente"}, 0),"✅","❌","🕓"), "⛔") & " ", "M" & IFERROR(CHOOSE(MATCH(INDEX(ControlMensual!L:L, MATCH(F7, ControlMensual!B:B, 0)), {"ok";"no";"pendiente"}, 0),"✅","❌","🕓"), "⛔") & " ", "J" & IFERROR(CHOOSE(MATCH(INDEX(ControlMensual!M:M, MATCH(F7, ControlMensual!B:B, 0)), {"ok";"no";"pendiente"}, 0),"✅","❌","🕓"), "⛔") & " ", "J" & IFERROR(CHOOSE(MATCH(INDEX(ControlMensual!N:N, MATCH(F7, ControlMensual!B:B, 0)), {"ok";"no";"pendiente"}, 0),"✅","❌","🕓"), "⛔") & " ", "A" & IFERROR(CHOOSE(MATCH(INDEX(ControlMensual!O:O, MATCH(F7, ControlMensual!B:B, 0)), {"ok";"no";"pendiente"}, 0),"✅","❌","🕓"), "⛔") & " ", "S" & IFERROR(CHOOSE(MATCH(INDEX(ControlMensual!P:P, MATCH(F7, ControlMensual!B:B, 0)), {"ok";"no";"pendiente"}, 0),"✅","❌","🕓"), "⛔") & " ", "O" & IFERROR(CHOOSE(MATCH(INDEX(ControlMensual!Q:Q, MATCH(F7, ControlMensual!B:B, 0)), {"ok";"no";"pendiente"}, 0),"✅","❌","🕓"), "⛔") & " ", "N" & IFERROR(CHOOSE(MATCH(INDEX(ControlMensual!R:R, MATCH(F7, ControlMensual!B:B, 0)), {"ok";"no";"pendiente"}, 0),"✅","❌","🕓"), "⛔") & " ", "D" & IFERROR(CHOOSE(MATCH(INDEX(ControlMensual!S:S, MATCH(F7, ControlMensual!B:B, 0)), {"ok";"no";"pendiente"}, 0),"✅","❌","🕓"), "⛔") ) ,"") ) -> Ya no cuenta con actualizaciones | U7: Si | V7: Si | W7: No | X7: No Aplica | Y7: =COUNTIF(U7:X7,"Si")/(COUNTIF(U7:X7,"Si")+COUNTIF(U7:X7,"No")) -> 0.66666667 | Z7: Sin Proyecto | AA7: Sin Fecha | AB7: Sistemas de Negocio | AC7: Sin Asignación | AD7: No | AE7: =VLOOKUP(E7,Falcon!B$2:C$558,2,FALSE) -> #REF! | AF7: =VLOOKUP(E7,VisionOne!B$2:C$229,2,FALSE) -> #REF! | AG7: =VLOOKUP(E7,Central!B$2:C$217,2,FALSE) -> #REF! | AH7: No | AJ7: Sin Asignación | AK7: No | AM7: =VLOOKUP(D7,'Copia de vInfo 2'!A:A,1,FALSE) -> #REF!
A8: 189 | B8: Alonso Ovalle | C8: Alonso Ovalle | D8: M2CAPPRD2 | E8: m2capprd2 | F8: 10.23.3.32 | G8: Producción | H8: Menú Andes (Pivote) | I8: Menú Andes (Pivote) | J8: Menú Andes | K8: Encendido | L8: Virtual | M8: Máquina Virtual VmWare | N8: No aplica | O8: Linux | P8: Oracle Linux 7 | Q8: Oracle Linux 7 (64-bit) | R8: =verificarVersionOS(Q8) -> #NAME? | S8: =IFERROR( IF(ISNUMBER(FIND("Soporte hasta: ", R8)), IF(VALUE(MID(R8,16,10))<TODAY(),"🟥 Obsoleto", IF(YEAR(VALUE(MID(R8,16,10)))=YEAR(TODAY()),"Actualizaciones disponibles", IF(YEAR(VALUE(MID(R8,16,10)))-YEAR(TODAY())=1,"Actualizaciones disponibles", IF(YEAR(VALUE(MID(R8,16,10)))-YEAR(TODAY())=2,"Actualizaciones disponibles", "Actualizaciones disponibles" ) ) ) ), "⛔ Sin datos" ), "⛔ Error en fecha" ) -> ⛔ Sin datos | T8: =IF(OR(S8 = "🟥 Obsoleto",S8 = "⛔ Sin datos"), "Ya no cuenta con actualizaciones", IFERROR( CONCATENATE( "E" & IFERROR(CHOOSE(MATCH(INDEX(ControlMensual!H:H, MATCH(F8, ControlMensual!B:B, 0)), {"ok";"no";"pendiente"}, 0),"✅","❌","🕓"), "⛔") & " ", "F" & IFERROR(CHOOSE(MATCH(INDEX(ControlMensual!I:I, MATCH(F8, ControlMensual!B:B, 0)), {"ok";"no";"pendiente"}, 0),"✅","❌","🕓"), "⛔") & " ", "M" & IFERROR(CHOOSE(MATCH(INDEX(ControlMensual!J:J, MATCH(F8, ControlMensual!B:B, 0)), {"ok";"no";"pendiente"}, 0),"✅","❌","🕓"), "⛔") & " ", "A" & IFERROR(CHOOSE(MATCH(INDEX(ControlMensual!K:K, MATCH(F8, ControlMensual!B:B, 0)), {"ok";"no";"pendiente"}, 0),"✅","❌","🕓"), "⛔") & " ", "M" & IFERROR(CHOOSE(MATCH(INDEX(ControlMensual!L:L, MATCH(F8, ControlMensual!B:B, 0)), {"ok";"no";"pendiente"}, 0),"✅","❌","🕓"), "⛔") & " ", "J" & IFERROR(CHOOSE(MATCH(INDEX(ControlMensual!M:M, MATCH(F8, ControlMensual!B:B, 0)), {"ok";"no";"pendiente"}, 0),"✅","❌","🕓"), "⛔") & " ", "J" & IFERROR(CHOOSE(MATCH(INDEX(ControlMensual!N:N, MATCH(F8, ControlMensual!B:B, 0)), {"ok";"no";"pendiente"}, 0),"✅","❌","🕓"), "⛔") & " ", "A" & IFERROR(CHOOSE(MATCH(INDEX(ControlMensual!O:O, MATCH(F8, ControlMensual!B:B, 0)), {"ok";"no";"pendiente"}, 0),"✅","❌","🕓"), "⛔") & " ", "S" & IFERROR(CHOOSE(MATCH(INDEX(ControlMensual!P:P, MATCH(F8, ControlMensual!B:B, 0)), {"ok";"no";"pendiente"}, 0),"✅","❌","🕓"), "⛔") & " ", "O" & IFERROR(CHOOSE(MATCH(INDEX(ControlMensual!Q:Q, MATCH(F8, ControlMensual!B:B, 0)), {"ok";"no";"pendiente"}, 0),"✅","❌","🕓"), "⛔") & " ", "N" & IFERROR(CHOOSE(MATCH(INDEX(ControlMensual!R:R, MATCH(F8, ControlMensual!B:B, 0)), {"ok";"no";"pendiente"}, 0),"✅","❌","🕓"), "⛔") & " ", "D" & IFERROR(CHOOSE(MATCH(INDEX(ControlMensual!S:S, MATCH(F8, ControlMensual!B:B, 0)), {"ok";"no";"pendiente"}, 0),"✅","❌","🕓"), "⛔") ) ,"") ) -> Ya no cuenta con actualizaciones | U8: Si | V8: Si | W8: No | X8: No aplica | Y8: =COUNTIF(U8:X8,"Si")/(COUNTIF(U8:X8,"Si")+COUNTIF(U8:X8,"No")) -> 0.66666667 | Z8: Sin Proyecto | AA8: Sin Fecha | AB8: Legales y Complementarios | AC8: Cristian Vera | AD8: No | AE8: =VLOOKUP(E8,Falcon!B$2:C$558,2,FALSE) -> #REF! | AF8: =VLOOKUP(E8,VisionOne!B$2:C$229,2,FALSE) -> #REF! | AG8: =VLOOKUP(D8,Central!B$2:C$217,2,FALSE) -> #REF! | AH8: No | AJ8: Cristian Vera | AK8: No | AM8: =VLOOKUP(D8,'Copia de vInfo 2'!A:A,1,FALSE) -> #REF! | AN8: Si
A9: 216 | B9: Alonso Ovalle | C9: Alonso Ovalle | D9: QA-WEBLOGIC-KURUB-RES | E9: kurub | F9: 10.23.4.99 | G9: QA | H9: =VLOOKUP(D9,'Inventario Plataformas OLD 260325'!I:Q,2,FALSE) -> #REF! | I9: Weblogic Transversal | J9: Servicios Transversales MDW | K9: Encendido | L9: Virtual | M9: Máquina Virtual VmWare | N9: No aplica | O9: Linux | P9: Red Hat Enterprise Linux 6 | Q9: Red Hat Enterprise Linux 6 (64-bit) | R9: =verificarVersionOS(Q9) -> #NAME? | S9: =IFERROR( IF(ISNUMBER(FIND("Soporte hasta: ", R9)), IF(VALUE(MID(R9,16,10))<TODAY(),"🟥 Obsoleto", IF(YEAR(VALUE(MID(R9,16,10)))=YEAR(TODAY()),"Actualizaciones disponibles", IF(YEAR(VALUE(MID(R9,16,10)))-YEAR(TODAY())=1,"Actualizaciones disponibles", IF(YEAR(VALUE(MID(R9,16,10)))-YEAR(TODAY())=2,"Actualizaciones disponibles", "Actualizaciones disponibles" ) ) ) ), "⛔ Sin datos" ), "⛔ Error en fecha" ) -> ⛔ Sin datos | T9: =IF(OR(S9 = "🟥 Obsoleto",S9 = "⛔ Sin datos"), "Ya no cuenta con actualizaciones", IFERROR( CONCATENATE( "E" & IFERROR(CHOOSE(MATCH(INDEX(ControlMensual!H:H, MATCH(F9, ControlMensual!B:B, 0)), {"ok";"no";"pendiente"}, 0),"✅","❌","🕓"), "⛔") & " ", "F" & IFERROR(CHOOSE(MATCH(INDEX(ControlMensual!I:I, MATCH(F9, ControlMensual!B:B, 0)), {"ok";"no";"pendiente"}, 0),"✅","❌","🕓"), "⛔") & " ", "M" & IFERROR(CHOOSE(MATCH(INDEX(ControlMensual!J:J, MATCH(F9, ControlMensual!B:B, 0)), {"ok";"no";"pendiente"}, 0),"✅","❌","🕓"), "⛔") & " ", "A" & IFERROR(CHOOSE(MATCH(INDEX(ControlMensual!K:K, MATCH(F9, ControlMensual!B:B, 0)), {"ok";"no";"pendiente"}, 0),"✅","❌","🕓"), "⛔") & " ", "M" & IFERROR(CHOOSE(MATCH(INDEX(ControlMensual!L:L, MATCH(F9, ControlMensual!B:B, 0)), {"ok";"no";"pendiente"}, 0),"✅","❌","🕓"), "⛔") & " ", "J" & IFERROR(CHOOSE(MATCH(INDEX(ControlMensual!M:M, MATCH(F9, ControlMensual!B:B, 0)), {"ok";"no";"pendiente"}, 0),"✅","❌","🕓"), "⛔") & " ", "J" & IFERROR(CHOOSE(MATCH(INDEX(ControlMensual!N:N, MATCH(F9, ControlMensual!B:B, 0)), {"ok";"no";"pendiente"}, 0),"✅","❌","🕓"), "⛔") & " ", "A" & IFERROR(CHOOSE(MATCH(INDEX(ControlMensual!O:O, MATCH(F9, ControlMensual!B:B, 0)), {"ok";"no";"pendiente"}, 0),"✅","❌","🕓"), "⛔") & " ", "S" & IFERROR(CHOOSE(MATCH(INDEX(ControlMensual!P:P, MATCH(F9, ControlMensual!B:B, 0)), {"ok";"no";"pendiente"}, 0),"✅","❌","🕓"), "⛔") & " ", "O" & IFERROR(CHOOSE(MATCH(INDEX(ControlMensual!Q:Q, MATCH(F9, ControlMensual!B:B, 0)), {"ok";"no";"pendiente"}, 0),"✅","❌","🕓"), "⛔") & " ", "N" & IFERROR(CHOOSE(MATCH(INDEX(ControlMensual!R:R, MATCH(F9, ControlMensual!B:B, 0)), {"ok";"no";"pendiente"}, 0),"✅","❌","🕓"), "⛔") & " ", "D" & IFERROR(CHOOSE(MATCH(INDEX(ControlMensual!S:S, MATCH(F9, ControlMensual!B:B, 0)), {"ok";"no";"pendiente"}, 0),"✅","❌","🕓"), "⛔") ) ,"") ) -> Ya no cuenta con actualizaciones | U9: Si | V9: Si | W9: No | X9: No aplica | Y9: =COUNTIF(U9:X9,"Si")/(COUNTIF(U9:X9,"Si")+COUNTIF(U9:X9,"No")) -> 0.66666667 | Z9: Sin Proyecto | AA9: Sin Fecha | AB9: Sistemas de Negocio | AC9: Sin Asignación | AD9: No | AE9: =VLOOKUP(E9,Falcon!B$2:C$558,2,FALSE) -> #REF! | AF9: =VLOOKUP(E9,VisionOne!B$2:C$229,2,FALSE) -> #REF! | AG9: =VLOOKUP(E9,Central!B$2:C$217,2,FALSE) -> #REF! | AH9: No | AJ9: Sin Asignación | AK9: No | AM9: =VLOOKUP(D9,'Copia de vInfo 2'!A:A,1,FALSE) -> #REF!
A10: 235 | B10: Alonso Ovalle | C10: Alonso Ovalle | D10: WEB-GORELY-DEV | E10: GORELY | F10: 10.23.1.214 | G10: Desarrollo | H10: Sin Software MDW | I10: Sucursal Virtual | J10: Portal Web Publico y SVP (1.0 | 1.5) | K10: Encendido | L10: Virtual | M10: Máquina Virtual VmWare | N10: No aplica | O10: Microsoft Windows | P10: Microsoft Windows Server 2008 | Q10: Microsoft Windows Server 2008 R2 (64-bit) | R10: =verificarVersionOS(Q10) -> #NAME? | S10: =IFERROR( IF(ISNUMBER(FIND("Soporte hasta: ", R10)), IF(VALUE(MID(R10,16,10))<TODAY(),"🟥 Obsoleto", IF(YEAR(VALUE(MID(R10,16,10)))=YEAR(TODAY()),"Actualizaciones disponibles", IF(YEAR(VALUE(MID(R10,16,10)))-YEAR(TODAY())=1,"Actualizaciones disponibles", IF(YEAR(VALUE(MID(R10,16,10)))-YEAR(TODAY())=2,"Actualizaciones disponibles", "Actualizaciones disponibles" ) ) ) ), "⛔ Sin datos" ), "⛔ Error en fecha" ) -> ⛔ Sin datos | T10: =IF(OR(S10 = "🟥 Obsoleto",S10 = "⛔ Sin datos"), "Ya no cuenta con actualizaciones", IFERROR( CONCATENATE( "E" & IFERROR(CHOOSE(MATCH(INDEX(ControlMensual!H:H, MATCH(F10, ControlMensual!B:B, 0)), {"ok";"no";"pendiente"}, 0),"✅","❌","🕓"), "⛔") & " ", "F" & IFERROR(CHOOSE(MATCH(INDEX(ControlMensual!I:I, MATCH(F10, ControlMensual!B:B, 0)), {"ok";"no";"pendiente"}, 0),"✅","❌","🕓"), "⛔") & " ", "M" & IFERROR(CHOOSE(MATCH(INDEX(ControlMensual!J:J, MATCH(F10, ControlMensual!B:B, 0)), {"ok";"no";"pendiente"}, 0),"✅","❌","🕓"), "⛔") & " ", "A" & IFERROR(CHOOSE(MATCH(INDEX(ControlMensual!K:K, MATCH(F10, ControlMensual!B:B, 0)), {"ok";"no";"pendiente"}, 0),"✅","❌","🕓"), "⛔") & " ", "M" & IFERROR(CHOOSE(MATCH(INDEX(ControlMensual!L:L, MATCH(F10, ControlMensual!B:B, 0)), {"ok";"no";"pendiente"}, 0),"✅","❌","🕓"), "⛔") & " ", "J" & IFERROR(CHOOSE(MATCH(INDEX(ControlMensual!M:M, MATCH(F10, ControlMensual!B:B, 0)), {"ok";"no";"pendiente"}, 0),"✅","❌","🕓"), "⛔") & " ", "J" & IFERROR(CHOOSE(MATCH(INDEX(ControlMensual!N:N, MATCH(F10, ControlMensual!B:B, 0)), {"ok";"no";"pendiente"}, 0),"✅","❌","🕓"), "⛔") & " ", "A" & IFERROR(CHOOSE(MATCH(INDEX(ControlMensual!O:O, MATCH(F10, ControlMensual!B:B, 0)), {"ok";"no";"pendiente"}, 0),"✅","❌","🕓"), "⛔") & " ", "S" & IFERROR(CHOOSE(MATCH(INDEX(ControlMensual!P:P, MATCH(F10, ControlMensual!B:B, 0)), {"ok";"no";"pendiente"}, 0),"✅","❌","🕓"), "⛔") & " ", "O" & IFERROR(CHOOSE(MATCH(INDEX(ControlMensual!Q:Q, MATCH(F10, ControlMensual!B:B, 0)), {"ok";"no";"pendiente"}, 0),"✅","❌","🕓"), "⛔") & " ", "N" & IFERROR(CHOOSE(MATCH(INDEX(ControlMensual!R:R, MATCH(F10, ControlMensual!B:B, 0)), {"ok";"no";"pendiente"}, 0),"✅","❌","🕓"), "⛔") & " ", "D" & IFERROR(CHOOSE(MATCH(INDEX(ControlMensual!S:S, MATCH(F10, ControlMensual!B:B, 0)), {"ok";"no";"pendiente"}, 0),"✅","❌","🕓"), "⛔") ) ,"") ) -> Ya no cuenta con actualizaciones | U10: Si | V10: No | W10: No | X10: No aplica | Y10: =COUNTIF(U10:X10,"Si")/(COUNTIF(U10:X10,"Si")+COUNTIF(U10:X10,"No")) -> 0.33333333 | Z10: Migración Portal Web Publico y SVP (1.0 | 1.5) | AA10: 45930 | AB10: Legales y Complementarios | AC10: Cristian Vera | AD10: Si | AE10: =VLOOKUP(D10,Falcon!B$2:C$558,2,FALSE) -> #REF! | AF10: =VLOOKUP(E10,VisionOne!B$2:C$229,2,FALSE) -> #REF! | AG10: =VLOOKUP(E10,Central!B$2:C$217,2,FALSE) -> #REF! | AH10: No | AJ10: Cristian Vera | AK10: Si | AL10: x | AM10: =VLOOKUP(D10,'Copia de vInfo 2'!A:A,1,FALSE) -> #REF! | AN10: Sí
A11: 236 | B11: Alonso Ovalle | C11: Alonso Ovalle | D11: WEB-KONE-QA | E11: KONE | F11: 10.23.1.240 | G11: QA | H11: Sin Software MDW | I11: Sucursal Virtual | J11: Portal Web Publico y SVP (1.0 | 1.5) | K11: Encendido | L11: Virtual | M11: Máquina Virtual VmWare | N11: No aplica | O11: Microsoft Windows | P11: Microsoft Windows Server 2008 | Q11: Microsoft Windows Server 2008 R2 (64-bit) | R11: =verificarVersionOS(Q11) -> #NAME? | S11: =IFERROR( IF(ISNUMBER(FIND("Soporte hasta: ", R11)), IF(VALUE(MID(R11,16,10))<TODAY(),"🟥 Obsoleto", IF(YEAR(VALUE(MID(R11,16,10)))=YEAR(TODAY()),"Actualizaciones disponibles", IF(YEAR(VALUE(MID(R11,16,10)))-YEAR(TODAY())=1,"Actualizaciones disponibles", IF(YEAR(VALUE(MID(R11,16,10)))-YEAR(TODAY())=2,"Actualizaciones disponibles", "Actualizaciones disponibles" ) ) ) ), "⛔ Sin datos" ), "⛔ Error en fecha" ) -> ⛔ Sin datos | T11: =IF(OR(S11 = "🟥 Obsoleto",S11 = "⛔ Sin datos"), "Ya no cuenta con actualizaciones", IFERROR( CONCATENATE( "E" & IFERROR(CHOOSE(MATCH(INDEX(ControlMensual!H:H, MATCH(F11, ControlMensual!B:B, 0)), {"ok";"no";"pendiente"}, 0),"✅","❌","🕓"), "⛔") & " ", "F" & IFERROR(CHOOSE(MATCH(INDEX(ControlMensual!I:I, MATCH(F11, ControlMensual!B:B, 0)), {"ok";"no";"pendiente"}, 0),"✅","❌","🕓"), "⛔") & " ", "M" & IFERROR(CHOOSE(MATCH(INDEX(ControlMensual!J:J, MATCH(F11, ControlMensual!B:B, 0)), {"ok";"no";"pendiente"}, 0),"✅","❌","🕓"), "⛔") & " ", "A" & IFERROR(CHOOSE(MATCH(INDEX(ControlMensual!K:K, MATCH(F11, ControlMensual!B:B, 0)), {"ok";"no";"pendiente"}, 0),"✅","❌","🕓"), "⛔") & " ", "M" & IFERROR(CHOOSE(MATCH(INDEX(ControlMensual!L:L, MATCH(F11, ControlMensual!B:B, 0)), {"ok";"no";"pendiente"}, 0),"✅","❌","🕓"), "⛔") & " ", "J" & IFERROR(CHOOSE(MATCH(INDEX(ControlMensual!M:M, MATCH(F11, ControlMensual!B:B, 0)), {"ok";"no";"pendiente"}, 0),"✅","❌","🕓"), "⛔") & " ", "J" & IFERROR(CHOOSE(MATCH(INDEX(ControlMensual!N:N, MATCH(F11, ControlMensual!B:B, 0)), {"ok";"no";"pendiente"}, 0),"✅","❌","🕓"), "⛔") & " ", "A" & IFERROR(CHOOSE(MATCH(INDEX(ControlMensual!O:O, MATCH(F11, ControlMensual!B:B, 0)), {"ok";"no";"pendiente"}, 0),"✅","❌","🕓"), "⛔") & " ", "S" & IFERROR(CHOOSE(MATCH(INDEX(ControlMensual!P:P, MATCH(F11, ControlMensual!B:B, 0)), {"ok";"no";"pendiente"}, 0),"✅","❌","🕓"), "⛔") & " ", "O" & IFERROR(CHOOSE(MATCH(INDEX(ControlMensual!Q:Q, MATCH(F11, ControlMensual!B:B, 0)), {"ok";"no";"pendiente"}, 0),"✅","❌","🕓"), "⛔") & " ", "N" & IFERROR(CHOOSE(MATCH(INDEX(ControlMensual!R:R, MATCH(F11, ControlMensual!B:B, 0)), {"ok";"no";"pendiente"}, 0),"✅","❌","🕓"), "⛔") & " ", "D" & IFERROR(CHOOSE(MATCH(INDEX(ControlMensual!S:S, MATCH(F11, ControlMensual!B:B, 0)), {"ok";"no";"pendiente"}, 0),"✅","❌","🕓"), "⛔") ) ,"") ) -> Ya no cuenta con actualizaciones | U11: Si | V11: No | W11: No | X11: No aplica | Y11: =COUNTIF(U11:X11,"Si")/(COUNTIF(U11:X11,"Si")+COUNTIF(U11:X11,"No")) -> 0.33333333 | Z11: Migración Portal Web Publico y SVP (1.0 | 1.5) | AA11: 45930 | AB11: Legales y Complementarios | AC11: Cristian Vera | AD11: Si | AE11: =VLOOKUP(D11,Falcon!B$2:C$558,2,FALSE) -> #REF! | AF11: =VLOOKUP(E11,VisionOne!B$2:C$229,2,FALSE) -> #REF! | AG11: =VLOOKUP(E11,Central!B$2:C$217,2,FALSE) -> #REF! | AH11: No | AJ11: Cristian Vera | AK11: Si | AL11: x | AM11: =VLOOKUP(D11,'Copia de vInfo 2'!A:A,1,FALSE) -> #REF! | AN11: Sí
A12: 240 | B12: Alonso Ovalle | C12: Alonso Ovalle | D12: WEB1.5-SANJOSE-DESA | E12: sanjose | F12: 10.23.1.43 | G12: Desarrollo | H12: Sin Software MDW | I12: Sucursal Virtual | J12: Portal Web Publico y SVP (1.0 | 1.5) | K12: Encendido | L12: Virtual | M12: Máquina Virtual VmWare | N12: No aplica | O12: Microsoft Windows | P12: Microsoft Windows Server 2003 | Q12: Microsoft Windows Server 2003 (32-bit) | R12: =verificarVersionOS(Q12) -> #NAME? | S12: =IFERROR( IF(ISNUMBER(FIND("Soporte hasta: ", R12)), IF(VALUE(MID(R12,16,10))<TODAY(),"🟥 Obsoleto", IF(YEAR(VALUE(MID(R12,16,10)))=YEAR(TODAY()),"Actualizaciones disponibles", IF(YEAR(VALUE(MID(R12,16,10)))-YEAR(TODAY())=1,"Actualizaciones disponibles", IF(YEAR(VALUE(MID(R12,16,10)))-YEAR(TODAY())=2,"Actualizaciones disponibles", "Actualizaciones disponibles" ) ) ) ), "⛔ Sin datos" ), "⛔ Error en fecha" ) -> ⛔ Sin datos | T12: =IF(OR(S12 = "🟥 Obsoleto",S12 = "⛔ Sin datos"), "Ya no cuenta con actualizaciones", IFERROR( CONCATENATE( "E" & IFERROR(CHOOSE(MATCH(INDEX(ControlMensual!H:H, MATCH(F12, ControlMensual!B:B, 0)), {"ok";"no";"pendiente"}, 0),"✅","❌","🕓"), "⛔") & " ", "F" & IFERROR(CHOOSE(MATCH(INDEX(ControlMensual!I:I, MATCH(F12, ControlMensual!B:B, 0)), {"ok";"no";"pendiente"}, 0),"✅","❌","🕓"), "⛔") & " ", "M" & IFERROR(CHOOSE(MATCH(INDEX(ControlMensual!J:J, MATCH(F12, ControlMensual!B:B, 0)), {"ok";"no";"pendiente"}, 0),"✅","❌","🕓"), "⛔") & " ", "A" & IFERROR(CHOOSE(MATCH(INDEX(ControlMensual!K:K, MATCH(F12, ControlMensual!B:B, 0)), {"ok";"no";"pendiente"}, 0),"✅","❌","🕓"), "⛔") & " ", "M" & IFERROR(CHOOSE(MATCH(INDEX(ControlMensual!L:L, MATCH(F12, ControlMensual!B:B, 0)), {"ok";"no";"pendiente"}, 0),"✅","❌","🕓"), "⛔") & " ", "J" & IFERROR(CHOOSE(MATCH(INDEX(ControlMensual!M:M, MATCH(F12, ControlMensual!B:B, 0)), {"ok";"no";"pendiente"}, 0),"✅","❌","🕓"), "⛔") & " ", "J" & IFERROR(CHOOSE(MATCH(INDEX(ControlMensual!N:N, MATCH(F12, ControlMensual!B:B, 0)), {"ok";"no";"pendiente"}, 0),"✅","❌","🕓"), "⛔") & " ", "A" & IFERROR(CHOOSE(MATCH(INDEX(ControlMensual!O:O, MATCH(F12, ControlMensual!B:B, 0)), {"ok";"no";"pendiente"}, 0),"✅","❌","🕓"), "⛔") & " ", "S" & IFERROR(CHOOSE(MATCH(INDEX(ControlMensual!P:P, MATCH(F12, ControlMensual!B:B, 0)), {"ok";"no";"pendiente"}, 0),"✅","❌","🕓"), "⛔") & " ", "O" & IFERROR(CHOOSE(MATCH(INDEX(ControlMensual!Q:Q, MATCH(F12, ControlMensual!B:B, 0)), {"ok";"no";"pendiente"}, 0),"✅","❌","🕓"), "⛔") & " ", "N" & IFERROR(CHOOSE(MATCH(INDEX(ControlMensual!R:R, MATCH(F12, ControlMensual!B:B, 0)), {"ok";"no";"pendiente"}, 0),"✅","❌","🕓"), "⛔") & " ", "D" & IFERROR(CHOOSE(MATCH(INDEX(ControlMensual!S:S, MATCH(F12, ControlMensual!B:B, 0)), {"ok";"no";"pendiente"}, 0),"✅","❌","🕓"), "⛔") ) ,"") ) -> Ya no cuenta con actualizaciones | U12: Si | V12: No | W12: No | X12: No aplica | Y12: =COUNTIF(U12:X12,"Si")/(COUNTIF(U12:X12,"Si")+COUNTIF(U12:X12,"No")) -> 0.33333333 | Z12: Migración Portal Web Publico y SVP (1.0 | 1.5) | AA12: 45930 | AB12: Legales y Complementarios | AC12: Cristian Vera | AD12: Si | AE12: =VLOOKUP(E12,Falcon!B$2:C$558,2,FALSE) -> #REF! | AF12: =VLOOKUP(E12,VisionOne!B$2:C$229,2,FALSE) -> #REF! | AG12: =VLOOKUP(E12,Central!B$2:C$217,2,FALSE) -> #REF! | AH12: No | AJ12: Cristian Vera | AK12: Si | AL12: x | AM12: =VLOOKUP(D12,'Copia de vInfo 2'!A:A,1,FALSE) -> #REF! | AN12: Sí
A13: 342 | B13: Sonda Cloud Privado | C13: Sonda | D13: BBDD-PUNTIAGUDO-PRO | E13: puntiagudo | F13: 10.23.4.91 | G13: Producción | H13: Sin Software MDW | I13: BD ADFS (Consumido por FICO) | J13: Motor de decisión FICO | K13: Encendido | L13: Virtual | M13: Máquina Virtual VmWare | N13: No aplica | O13: Microsoft Windows | P13: Microsoft Windows Server 2012 | Q13: Microsoft Windows Server 2012 (64-bit) | R13: =verificarVersionOS(Q13) -> #NAME? | S13: =IFERROR( IF(ISNUMBER(FIND("Soporte hasta: ", R13)), IF(VALUE(MID(R13,16,10))<TODAY(),"🟥 Obsoleto", IF(YEAR(VALUE(MID(R13,16,10)))=YEAR(TODAY()),"Actualizaciones disponibles", IF(YEAR(VALUE(MID(R13,16,10)))-YEAR(TODAY())=1,"Actualizaciones disponibles", IF(YEAR(VALUE(MID(R13,16,10)))-YEAR(TODAY())=2,"Actualizaciones disponibles", "Actualizaciones disponibles" ) ) ) ), "⛔ Sin datos" ), "⛔ Error en fecha" ) -> ⛔ Sin datos | T13: =IF(OR(S13 = "🟥 Obsoleto",S13 = "⛔ Sin datos"), "Ya no cuenta con actualizaciones", IFERROR( CONCATENATE( "E" & IFERROR(CHOOSE(MATCH(INDEX(ControlMensual!H:H, MATCH(F13, ControlMensual!B:B, 0)), {"ok";"no";"pendiente"}, 0),"✅","❌","🕓"), "⛔") & " ", "F" & IFERROR(CHOOSE(MATCH(INDEX(ControlMensual!I:I, MATCH(F13, ControlMensual!B:B, 0)), {"ok";"no";"pendiente"}, 0),"✅","❌","🕓"), "⛔") & " ", "M" & IFERROR(CHOOSE(MATCH(INDEX(ControlMensual!J:J, MATCH(F13, ControlMensual!B:B, 0)), {"ok";"no";"pendiente"}, 0),"✅","❌","🕓"), "⛔") & " ", "A" & IFERROR(CHOOSE(MATCH(INDEX(ControlMensual!K:K, MATCH(F13, ControlMensual!B:B, 0)), {"ok";"no";"pendiente"}, 0),"✅","❌","🕓"), "⛔") & " ", "M" & IFERROR(CHOOSE(MATCH(INDEX(ControlMensual!L:L, MATCH(F13, ControlMensual!B:B, 0)), {"ok";"no";"pendiente"}, 0),"✅","❌","🕓"), "⛔") & " ", "J" & IFERROR(CHOOSE(MATCH(INDEX(ControlMensual!M:M, MATCH(F13, ControlMensual!B:B, 0)), {"ok";"no";"pendiente"}, 0),"✅","❌","🕓"), "⛔") & " ", "J" & IFERROR(CHOOSE(MATCH(INDEX(ControlMensual!N:N, MATCH(F13, ControlMensual!B:B, 0)), {"ok";"no";"pendiente"}, 0),"✅","❌","🕓"), "⛔") & " ", "A" & IFERROR(CHOOSE(MATCH(INDEX(ControlMensual!O:O, MATCH(F13, ControlMensual!B:B, 0)), {"ok";"no";"pendiente"}, 0),"✅","❌","🕓"), "⛔") & " ", "S" & IFERROR(CHOOSE(MATCH(INDEX(ControlMensual!P:P, MATCH(F13, ControlMensual!B:B, 0)), {"ok";"no";"pendiente"}, 0),"✅","❌","🕓"), "⛔") & " ", "O" & IFERROR(CHOOSE(MATCH(INDEX(ControlMensual!Q:Q, MATCH(F13, ControlMensual!B:B, 0)), {"ok";"no";"pendiente"}, 0),"✅","❌","🕓"), "⛔") & " ", "N" & IFERROR(CHOOSE(MATCH(INDEX(ControlMensual!R:R, MATCH(F13, ControlMensual!B:B, 0)), {"ok";"no";"pendiente"}, 0),"✅","❌","🕓"), "⛔") & " ", "D" & IFERROR(CHOOSE(MATCH(INDEX(ControlMensual!S:S, MATCH(F13, ControlMensual!B:B, 0)), {"ok";"no";"pendiente"}, 0),"✅","❌","🕓"), "⛔") ) ,"") ) -> Ya no cuenta con actualizaciones | U13: Si | V13: Si | W13: No | X13: No aplica | Y13: =COUNTIF(U13:X13,"Si")/(COUNTIF(U13:X13,"Si")+COUNTIF(U13:X13,"No")) -> 0.66666667 | Z13: Migración FICO | AA13: 45930 | AB13: Sistemas Financieros | AC13: Claudia León | AD13: No | AE13: =VLOOKUP(D13,Falcon!B$2:C$558,2,FALSE) -> #REF! | AF13: =VLOOKUP(E13,VisionOne!B$2:C$229,2,FALSE) -> #REF! | AG13: =VLOOKUP(E13,Central!B$2:C$217,2,FALSE) -> #REF! | AH13: No | AJ13: Patricio Alegría | AK13: Si | AL13: x | AM13: =VLOOKUP(D13,'Copia de vInfo 2'!A:A,1,FALSE) -> #REF! | AN13: Sí
A14: 372 | B14: Sonda Cloud Privado | C14: Sonda | D14: dmpsprd1gtw | E14: dmpsprd1gtw | F14: 172.29.191.66 | G14: Producción | H14: DMPS 4 (FICO) | I14: Motor de decisión FICO | J14: Motor de decisión FICO | K14: Encendido | L14: Virtual | M14: Máquina Virtual VmWare | N14: No aplica | O14: Linux | P14: Red Hat Enterprise Linux 7 | Q14: Red Hat Enterprise Linux 7 (64-bit) | R14: =verificarVersionOS(Q14) -> #NAME? | S14: =IFERROR( IF(ISNUMBER(FIND("Soporte hasta: ", R14)), IF(VALUE(MID(R14,16,10))<TODAY(),"🟥 Obsoleto", IF(YEAR(VALUE(MID(R14,16,10)))=YEAR(TODAY()),"Actualizaciones disponibles", IF(YEAR(VALUE(MID(R14,16,10)))-YEAR(TODAY())=1,"Actualizaciones disponibles", IF(YEAR(VALUE(MID(R14,16,10)))-YEAR(TODAY())=2,"Actualizaciones disponibles", "Actualizaciones disponibles" ) ) ) ), "⛔ Sin datos" ), "⛔ Error en fecha" ) -> ⛔ Sin datos | T14: =IF(OR(S14 = "🟥 Obsoleto",S14 = "⛔ Sin datos"), "Ya no cuenta con actualizaciones", IFERROR( CONCATENATE( "E" & IFERROR(CHOOSE(MATCH(INDEX(ControlMensual!H:H, MATCH(F14, ControlMensual!B:B, 0)), {"ok";"no";"pendiente"}, 0),"✅","❌","🕓"), "⛔") & " ", "F" & IFERROR(CHOOSE(MATCH(INDEX(ControlMensual!I:I, MATCH(F14, ControlMensual!B:B, 0)), {"ok";"no";"pendiente"}, 0),"✅","❌","🕓"), "⛔") & " ", "M" & IFERROR(CHOOSE(MATCH(INDEX(ControlMensual!J:J, MATCH(F14, ControlMensual!B:B, 0)), {"ok";"no";"pendiente"}, 0),"✅","❌","🕓"), "⛔") & " ", "A" & IFERROR(CHOOSE(MATCH(INDEX(ControlMensual!K:K, MATCH(F14, ControlMensual!B:B, 0)), {"ok";"no";"pendiente"}, 0),"✅","❌","🕓"), "⛔") & " ", "M" & IFERROR(CHOOSE(MATCH(INDEX(ControlMensual!L:L, MATCH(F14, ControlMensual!B:B, 0)), {"ok";"no";"pendiente"}, 0),"✅","❌","🕓"), "⛔") & " ", "J" & IFERROR(CHOOSE(MATCH(INDEX(ControlMensual!M:M, MATCH(F14, ControlMensual!B:B, 0)), {"ok";"no";"pendiente"}, 0),"✅","❌","🕓"), "⛔") & " ", "J" & IFERROR(CHOOSE(MATCH(INDEX(ControlMensual!N:N, MATCH(F14, ControlMensual!B:B, 0)), {"ok";"no";"pendiente"}, 0),"✅","❌","🕓"), "⛔") & " ", "A" & IFERROR(CHOOSE(MATCH(INDEX(ControlMensual!O:O, MATCH(F14, ControlMensual!B:B, 0)), {"ok";"no";"pendiente"}, 0),"✅","❌","🕓"), "⛔") & " ", "S" & IFERROR(CHOOSE(MATCH(INDEX(ControlMensual!P:P, MATCH(F14, ControlMensual!B:B, 0)), {"ok";"no";"pendiente"}, 0),"✅","❌","🕓"), "⛔") & " ", "O" & IFERROR(CHOOSE(MATCH(INDEX(ControlMensual!Q:Q, MATCH(F14, ControlMensual!B:B, 0)), {"ok";"no";"pendiente"}, 0),"✅","❌","🕓"), "⛔") & " ", "N" & IFERROR(CHOOSE(MATCH(INDEX(ControlMensual!R:R, MATCH(F14, ControlMensual!B:B, 0)), {"ok";"no";"pendiente"}, 0),"✅","❌","🕓"), "⛔") & " ", "D" & IFERROR(CHOOSE(MATCH(INDEX(ControlMensual!S:S, MATCH(F14, ControlMensual!B:B, 0)), {"ok";"no";"pendiente"}, 0),"✅","❌","🕓"), "⛔") ) ,"") ) -> Ya no cuenta con actualizaciones | U14: Si | V14: Si | W14: No | X14: No aplica | Y14: =COUNTIF(U14:X14,"Si")/(COUNTIF(U14:X14,"Si")+COUNTIF(U14:X14,"No")) -> 0.66666667 | Z14: Migración FICO | AA14: 45930 | AB14: Sistemas Financieros | AC14: Claudia León | AD14: No | AE14: =VLOOKUP(D14,Falcon!B$2:C$558,2,FALSE) -> #REF! | AF14: =VLOOKUP(E14,VisionOne!B$2:C$229,2,FALSE) -> #REF! | AG14: =VLOOKUP(D14,Central!B$2:C$217,2,FALSE) -> #REF! | AH14: No | AJ14: Patricio Alegría | AK14: Si | AL14: x | AM14: =VLOOKUP(D14,'Copia de vInfo 2'!A:A,1,FALSE) -> #REF! | AN14: Sí
A15: 373 | B15: Sonda Cloud Privado | C15: Sonda | D15: dmpsprd2dpc | E15: dmpsprd2dpc | F15: 172.29.191.67 | G15: Producción | H15: DMPS 4 (FICO) | I15: Motor de decisión FICO | J15: Motor de decisión FICO | K15: Encendido | L15: Virtual | M15: Máquina Virtual VmWare | N15: No aplica | O15: Linux | P15: Red Hat Enterprise Linux 7 | Q15: Red Hat Enterprise Linux 7 (64-bit) | R15: =verificarVersionOS(Q15) -> #NAME? | S15: =IFERROR( IF(ISNUMBER(FIND("Soporte hasta: ", R15)), IF(VALUE(MID(R15,16,10))<TODAY(),"🟥 Obsoleto", IF(YEAR(VALUE(MID(R15,16,10)))=YEAR(TODAY()),"Actualizaciones disponibles", IF(YEAR(VALUE(MID(R15,16,10)))-YEAR(TODAY())=1,"Actualizaciones disponibles", IF(YEAR(VALUE(MID(R15,16,10)))-YEAR(TODAY())=2,"Actualizaciones disponibles", "Actualizaciones disponibles" ) ) ) ), "⛔ Sin datos" ), "⛔ Error en fecha" ) -> ⛔ Sin datos | T15: =IF(OR(S15 = "🟥 Obsoleto",S15 = "⛔ Sin datos"), "Ya no cuenta con actualizaciones", IFERROR( CONCATENATE( "E" & IFERROR(CHOOSE(MATCH(INDEX(ControlMensual!H:H, MATCH(F15, ControlMensual!B:B, 0)), {"ok";"no";"pendiente"}, 0),"✅","❌","🕓"), "⛔") & " ", "F" & IFERROR(CHOOSE(MATCH(INDEX(ControlMensual!I:I, MATCH(F15, ControlMensual!B:B, 0)), {"ok";"no";"pendiente"}, 0),"✅","❌","🕓"), "⛔") & " ", "M" & IFERROR(CHOOSE(MATCH(INDEX(ControlMensual!J:J, MATCH(F15, ControlMensual!B:B, 0)), {"ok";"no";"pendiente"}, 0),"✅","❌","🕓"), "⛔") & " ", "A" & IFERROR(CHOOSE(MATCH(INDEX(ControlMensual!K:K, MATCH(F15, ControlMensual!B:B, 0)), {"ok";"no";"pendiente"}, 0),"✅","❌","🕓"), "⛔") & " ", "M" & IFERROR(CHOOSE(MATCH(INDEX(ControlMensual!L:L, MATCH(F15, ControlMensual!B:B, 0)), {"ok";"no";"pendiente"}, 0),"✅","❌","🕓"), "⛔") & " ", "J" & IFERROR(CHOOSE(MATCH(INDEX(ControlMensual!M:M, MATCH(F15, ControlMensual!B:B, 0)), {"ok";"no";"pendiente"}, 0),"✅","❌","🕓"), "⛔") & " ", "J" & IFERROR(CHOOSE(MATCH(INDEX(ControlMensual!N:N, MATCH(F15, ControlMensual!B:B, 0)), {"ok";"no";"pendiente"}, 0),"✅","❌","🕓"), "⛔") & " ", "A" & IFERROR(CHOOSE(MATCH(INDEX(ControlMensual!O:O, MATCH(F15, ControlMensual!B:B, 0)), {"ok";"no";"pendiente"}, 0),"✅","❌","🕓"), "⛔") & " ", "S" & IFERROR(CHOOSE(MATCH(INDEX(ControlMensual!P:P, MATCH(F15, ControlMensual!B:B, 0)), {"ok";"no";"pendiente"}, 0),"✅","❌","🕓"), "⛔") & " ", "O" & IFERROR(CHOOSE(MATCH(INDEX(ControlMensual!Q:Q, MATCH(F15, ControlMensual!B:B, 0)), {"ok";"no";"pendiente"}, 0),"✅","❌","🕓"), "⛔") & " ", "N" & IFERROR(CHOOSE(MATCH(INDEX(ControlMensual!R:R, MATCH(F15, ControlMensual!B:B, 0)), {"ok";"no";"pendiente"}, 0),"✅","❌","🕓"), "⛔") & " ", "D" & IFERROR(CHOOSE(MATCH(INDEX(ControlMensual!S:S, MATCH(F15, ControlMensual!B:B, 0)), {"ok";"no";"pendiente"}, 0),"✅","❌","🕓"), "⛔") ) ,"") ) -> Ya no cuenta con actualizaciones | U15: Si | V15: Si | W15: No | X15: No aplica | Y15: =COUNTIF(U15:X15,"Si")/(COUNTIF(U15:X15,"Si")+COUNTIF(U15:X15,"No")) -> 0.66666667 | Z15: Migración FICO | AA15: 45930 | AB15: Sistemas Financieros | AC15: Claudia León | AD15: No | AE15: =VLOOKUP(D15,Falcon!B$2:C$558,2,FALSE) -> #REF! | AF15: =VLOOKUP(E15,VisionOne!B$2:C$229,2,FALSE) -> #REF! | AG15: =VLOOKUP(D15,Central!B$2:C$217,2,FALSE) -> #REF! | AH15: No | AJ15: Patricio Alegría | AK15: Si | AL15: x | AM15: =VLOOKUP(D15,'Copia de vInfo 2'!A:A,1,FALSE) -> #REF! | AN15: Sí
A16: 374 | B16: Sonda Cloud Privado | C16: Sonda | D16: dmpsprd3vsc | E16: dmpsprd3vsc | F16: 172.29.191.68 | G16: Producción | H16: DMPS 4 (FICO) | I16: Motor de decisión FICO | J16: Motor de decisión FICO | K16: Encendido | L16: Virtual | M16: Máquina Virtual VmWare | N16: No aplica | O16: Linux | P16: Red Hat Enterprise Linux 7 | Q16: Red Hat Enterprise Linux 7 (64-bit) | R16: =verificarVersionOS(Q16) -> #NAME? | S16: =IFERROR( IF(ISNUMBER(FIND("Soporte hasta: ", R16)), IF(VALUE(MID(R16,16,10))<TODAY(),"🟥 Obsoleto", IF(YEAR(VALUE(MID(R16,16,10)))=YEAR(TODAY()),"Actualizaciones disponibles", IF(YEAR(VALUE(MID(R16,16,10)))-YEAR(TODAY())=1,"Actualizaciones disponibles", IF(YEAR(VALUE(MID(R16,16,10)))-YEAR(TODAY())=2,"Actualizaciones disponibles", "Actualizaciones disponibles" ) ) ) ), "⛔ Sin datos" ), "⛔ Error en fecha" ) -> ⛔ Sin datos | T16: =IF(OR(S16 = "🟥 Obsoleto",S16 = "⛔ Sin datos"), "Ya no cuenta con actualizaciones", IFERROR( CONCATENATE( "E" & IFERROR(CHOOSE(MATCH(INDEX(ControlMensual!H:H, MATCH(F16, ControlMensual!B:B, 0)), {"ok";"no";"pendiente"}, 0),"✅","❌","🕓"), "⛔") & " ", "F" & IFERROR(CHOOSE(MATCH(INDEX(ControlMensual!I:I, MATCH(F16, ControlMensual!B:B, 0)), {"ok";"no";"pendiente"}, 0),"✅","❌","🕓"), "⛔") & " ", "M" & IFERROR(CHOOSE(MATCH(INDEX(ControlMensual!J:J, MATCH(F16, ControlMensual!B:B, 0)), {"ok";"no";"pendiente"}, 0),"✅","❌","🕓"), "⛔") & " ", "A" & IFERROR(CHOOSE(MATCH(INDEX(ControlMensual!K:K, MATCH(F16, ControlMensual!B:B, 0)), {"ok";"no";"pendiente"}, 0),"✅","❌","🕓"), "⛔") & " ", "M" & IFERROR(CHOOSE(MATCH(INDEX(ControlMensual!L:L, MATCH(F16, ControlMensual!B:B, 0)), {"ok";"no";"pendiente"}, 0),"✅","❌","🕓"), "⛔") & " ", "J" & IFERROR(CHOOSE(MATCH(INDEX(ControlMensual!M:M, MATCH(F16, ControlMensual!B:B, 0)), {"ok";"no";"pendiente"}, 0),"✅","❌","🕓"), "⛔") & " ", "J" & IFERROR(CHOOSE(MATCH(INDEX(ControlMensual!N:N, MATCH(F16, ControlMensual!B:B, 0)), {"ok";"no";"pendiente"}, 0),"✅","❌","🕓"), "⛔") & " ", "A" & IFERROR(CHOOSE(MATCH(INDEX(ControlMensual!O:O, MATCH(F16, ControlMensual!B:B, 0)), {"ok";"no";"pendiente"}, 0),"✅","❌","🕓"), "⛔") & " ", "S" & IFERROR(CHOOSE(MATCH(INDEX(ControlMensual!P:P, MATCH(F16, ControlMensual!B:B, 0)), {"ok";"no";"pendiente"}, 0),"✅","❌","🕓"), "⛔") & " ", "O" & IFERROR(CHOOSE(MATCH(INDEX(ControlMensual!Q:Q, MATCH(F16, ControlMensual!B:B, 0)), {"ok";"no";"pendiente"}, 0),"✅","❌","🕓"), "⛔") & " ", "N" & IFERROR(CHOOSE(MATCH(INDEX(ControlMensual!R:R, MATCH(F16, ControlMensual!B:B, 0)), {"ok";"no";"pendiente"}, 0),"✅","❌","🕓"), "⛔") & " ", "D" & IFERROR(CHOOSE(MATCH(INDEX(ControlMensual!S:S, MATCH(F16, ControlMensual!B:B, 0)), {"ok";"no";"pendiente"}, 0),"✅","❌","🕓"), "⛔") ) ,"") ) -> Ya no cuenta con actualizaciones | U16: Si | V16: Si | W16: No | X16: No aplica | Y16: =COUNTIF(U16:X16,"Si")/(COUNTIF(U16:X16,"Si")+COUNTIF(U16:X16,"No")) -> 0.66666667 | Z16: Migración FICO | AA16: 45930 | AB16: Sistemas Financieros | AC16: Claudia León | AD16: No | AE16: =VLOOKUP(D16,Falcon!B$2:C$558,2,FALSE) -> #REF! | AF16: =VLOOKUP(E16,VisionOne!B$2:C$229,2,FALSE) -> #REF! | AG16: =VLOOKUP(D16,Central!B$2:C$217,2,FALSE) -> #REF! | AH16: No | AJ16: Patricio Alegría | AK16: Si | AL16: x | AM16: =VLOOKUP(D16,'Copia de vInfo 2'!A:A,1,FALSE) -> #REF! | AN16: Sí
A17: 375 | B17: Sonda Cloud Privado | C17: Sonda | D17: dmpsprd4dpm | E17: dmpsprd4dpm | F17: 172.29.191.69 | G17: Producción | H17: DMPS 4 (FICO) | I17: Motor de decisión FICO | J17: Motor de decisión FICO | K17: Encendido | L17: Virtual | M17: Máquina Virtual VmWare | N17: No aplica | O17: Linux | P17: Red Hat Enterprise Linux 7 | Q17: Red Hat Enterprise Linux 7 (64-bit) | R17: =verificarVersionOS(Q17) -> #NAME? | S17: =IFERROR( IF(ISNUMBER(FIND("Soporte hasta: ", R17)), IF(VALUE(MID(R17,16,10))<TODAY(),"🟥 Obsoleto", IF(YEAR(VALUE(MID(R17,16,10)))=YEAR(TODAY()),"Actualizaciones disponibles", IF(YEAR(VALUE(MID(R17,16,10)))-YEAR(TODAY())=1,"Actualizaciones disponibles", IF(YEAR(VALUE(MID(R17,16,10)))-YEAR(TODAY())=2,"Actualizaciones disponibles", "Actualizaciones disponibles" ) ) ) ), "⛔ Sin datos" ), "⛔ Error en fecha" ) -> ⛔ Sin datos | T17: =IF(OR(S17 = "🟥 Obsoleto",S17 = "⛔ Sin datos"), "Ya no cuenta con actualizaciones", IFERROR( CONCATENATE( "E" & IFERROR(CHOOSE(MATCH(INDEX(ControlMensual!H:H, MATCH(F17, ControlMensual!B:B, 0)), {"ok";"no";"pendiente"}, 0),"✅","❌","🕓"), "⛔") & " ", "F" & IFERROR(CHOOSE(MATCH(INDEX(ControlMensual!I:I, MATCH(F17, ControlMensual!B:B, 0)), {"ok";"no";"pendiente"}, 0),"✅","❌","🕓"), "⛔") & " ", "M" & IFERROR(CHOOSE(MATCH(INDEX(ControlMensual!J:J, MATCH(F17, ControlMensual!B:B, 0)), {"ok";"no";"pendiente"}, 0),"✅","❌","🕓"), "⛔") & " ", "A" & IFERROR(CHOOSE(MATCH(INDEX(ControlMensual!K:K, MATCH(F17, ControlMensual!B:B, 0)), {"ok";"no";"pendiente"}, 0),"✅","❌","🕓"), "⛔") & " ", "M" & IFERROR(CHOOSE(MATCH(INDEX(ControlMensual!L:L, MATCH(F17, ControlMensual!B:B, 0)), {"ok";"no";"pendiente"}, 0),"✅","❌","🕓"), "⛔") & " ", "J" & IFERROR(CHOOSE(MATCH(INDEX(ControlMensual!M:M, MATCH(F17, ControlMensual!B:B, 0)), {"ok";"no";"pendiente"}, 0),"✅","❌","🕓"), "⛔") & " ", "J" & IFERROR(CHOOSE(MATCH(INDEX(ControlMensual!N:N, MATCH(F17, ControlMensual!B:B, 0)), {"ok";"no";"pendiente"}, 0),"✅","❌","🕓"), "⛔") & " ", "A" & IFERROR(CHOOSE(MATCH(INDEX(ControlMensual!O:O, MATCH(F17, ControlMensual!B:B, 0)), {"ok";"no";"pendiente"}, 0),"✅","❌","🕓"), "⛔") & " ", "S" & IFERROR(CHOOSE(MATCH(INDEX(ControlMensual!P:P, MATCH(F17, ControlMensual!B:B, 0)), {"ok";"no";"pendiente"}, 0),"✅","❌","🕓"), "⛔") & " ", "O" & IFERROR(CHOOSE(MATCH(INDEX(ControlMensual!Q:Q, MATCH(F17, ControlMensual!B:B, 0)), {"ok";"no";"pendiente"}, 0),"✅","❌","🕓"), "⛔") & " ", "N" & IFERROR(CHOOSE(MATCH(INDEX(ControlMensual!R:R, MATCH(F17, ControlMensual!B:B, 0)), {"ok";"no";"pendiente"}, 0),"✅","❌","🕓"), "⛔") & " ", "D" & IFERROR(CHOOSE(MATCH(INDEX(ControlMensual!S:S, MATCH(F17, ControlMensual!B:B, 0)), {"ok";"no";"pendiente"}, 0),"✅","❌","🕓"), "⛔") ) ,"") ) -> Ya no cuenta con actualizaciones | U17: Si | V17: Si | W17: No | X17: No aplica | Y17: =COUNTIF(U17:X17,"Si")/(COUNTIF(U17:X17,"Si")+COUNTIF(U17:X17,"No")) -> 0.66666667 | Z17: Migración FICO | AA17: 45930 | AB17: Sistemas Financieros | AC17: Claudia León | AD17: No | AE17: =VLOOKUP(D17,Falcon!B$2:C$558,2,FALSE) -> #REF! | AF17: =VLOOKUP(E17,VisionOne!B$2:C$229,2,FALSE) -> #REF! | AG17: =VLOOKUP(D17,Central!B$2:C$217,2,FALSE) -> #REF! | AH17: No | AJ17: Patricio Alegría | AK17: Si | AL17: x | AN17: Sí
A18: 376 | B18: Sonda Cloud Privado | C18: Sonda | D18: dmpsprd5dcp | E18: dmpsprd5dcp | F18: 172.29.191.70 | G18: Producción | H18: DMPS 4 (FICO) | I18: Motor de decisión FICO | J18: Motor de decisión FICO | K18: Encendido | L18: Virtual | M18: Máquina Virtual VmWare | N18: No aplica | O18: Linux | P18: Red Hat Enterprise Linux 7 | Q18: Red Hat Enterprise Linux 7 (64-bit) | R18: =verificarVersionOS(Q18) -> #NAME? | S18: =IFERROR( IF(ISNUMBER(FIND("Soporte hasta: ", R18)), IF(VALUE(MID(R18,16,10))<TODAY(),"🟥 Obsoleto", IF(YEAR(VALUE(MID(R18,16,10)))=YEAR(TODAY()),"Actualizaciones disponibles", IF(YEAR(VALUE(MID(R18,16,10)))-YEAR(TODAY())=1,"Actualizaciones disponibles", IF(YEAR(VALUE(MID(R18,16,10)))-YEAR(TODAY())=2,"Actualizaciones disponibles", "Actualizaciones disponibles" ) ) ) ), "⛔ Sin datos" ), "⛔ Error en fecha" ) -> ⛔ Sin datos | T18: =IF(OR(S18 = "🟥 Obsoleto",S18 = "⛔ Sin datos"), "Ya no cuenta con actualizaciones", IFERROR( CONCATENATE( "E" & IFERROR(CHOOSE(MATCH(INDEX(ControlMensual!H:H, MATCH(F18, ControlMensual!B:B, 0)), {"ok";"no";"pendiente"}, 0),"✅","❌","🕓"), "⛔") & " ", "F" & IFERROR(CHOOSE(MATCH(INDEX(ControlMensual!I:I, MATCH(F18, ControlMensual!B:B, 0)), {"ok";"no";"pendiente"}, 0),"✅","❌","🕓"), "⛔") & " ", "M" & IFERROR(CHOOSE(MATCH(INDEX(ControlMensual!J:J, MATCH(F18, ControlMensual!B:B, 0)), {"ok";"no";"pendiente"}, 0),"✅","❌","🕓"), "⛔") & " ", "A" & IFERROR(CHOOSE(MATCH(INDEX(ControlMensual!K:K, MATCH(F18, ControlMensual!B:B, 0)), {"ok";"no";"pendiente"}, 0),"✅","❌","🕓"), "⛔") & " ", "M" & IFERROR(CHOOSE(MATCH(INDEX(ControlMensual!L:L, MATCH(F18, ControlMensual!B:B, 0)), {"ok";"no";"pendiente"}, 0),"✅","❌","🕓"), "⛔") & " ", "J" & IFERROR(CHOOSE(MATCH(INDEX(ControlMensual!M:M, MATCH(F18, ControlMensual!B:B, 0)), {"ok";"no";"pendiente"}, 0),"✅","❌","🕓"), "⛔") & " ", "J" & IFERROR(CHOOSE(MATCH(INDEX(ControlMensual!N:N, MATCH(F18, ControlMensual!B:B, 0)), {"ok";"no";"pendiente"}, 0),"✅","❌","🕓"), "⛔") & " ", "A" & IFERROR(CHOOSE(MATCH(INDEX(ControlMensual!O:O, MATCH(F18, ControlMensual!B:B, 0)), {"ok";"no";"pendiente"}, 0),"✅","❌","🕓"), "⛔") & " ", "S" & IFERROR(CHOOSE(MATCH(INDEX(ControlMensual!P:P, MATCH(F18, ControlMensual!B:B, 0)), {"ok";"no";"pendiente"}, 0),"✅","❌","🕓"), "⛔") & " ", "O" & IFERROR(CHOOSE(MATCH(INDEX(ControlMensual!Q:Q, MATCH(F18, ControlMensual!B:B, 0)), {"ok";"no";"pendiente"}, 0),"✅","❌","🕓"), "⛔") & " ", "N" & IFERROR(CHOOSE(MATCH(INDEX(ControlMensual!R:R, MATCH(F18, ControlMensual!B:B, 0)), {"ok";"no";"pendiente"}, 0),"✅","❌","🕓"), "⛔") & " ", "D" & IFERROR(CHOOSE(MATCH(INDEX(ControlMensual!S:S, MATCH(F18, ControlMensual!B:B, 0)), {"ok";"no";"pendiente"}, 0),"✅","❌","🕓"), "⛔") ) ,"") ) -> Ya no cuenta con actualizaciones | U18: Si | V18: Si | W18: No | X18: No aplica | Y18: =COUNTIF(U18:X18,"Si")/(COUNTIF(U18:X18,"Si")+COUNTIF(U18:X18,"No")) -> 0.66666667 | Z18: Migración FICO | AA18: 45930 | AB18: Sistemas Financieros | AC18: Claudia León | AD18: No | AE18: =VLOOKUP(E18,Falcon!B$2:C$558,2,FALSE) -> #REF! | AF18: =VLOOKUP(E18,VisionOne!B$2:C$229,2,FALSE) -> #REF! | AG18: =VLOOKUP(E18,Central!B$2:C$217,2,FALSE) -> #REF! | AH18: No | AJ18: Patricio Alegría | AK18: Si | AL18: x | AM18: =VLOOKUP(D18,'Copia de vInfo 2'!A:A,1,FALSE) -> #REF! | AN18: Sí
A19: 377 | B19: Sonda Cloud Privado | C19: Sonda | D19: dmpsprd6dcm | E19: dmpsprd6dcm | F19: 172.29.191.71 | G19: Producción | H19: DMPS 4 (FICO) | I19: Motor de decisión FICO | J19: Motor de decisión FICO | K19: Encendido | L19: Virtual | M19: Máquina Virtual VmWare | N19: No aplica | O19: Linux | P19: Red Hat Enterprise Linux 7 | Q19: Red Hat Enterprise Linux 7 (64-bit) | R19: =verificarVersionOS(Q19) -> #NAME? | S19: =IFERROR( IF(ISNUMBER(FIND("Soporte hasta: ", R19)), IF(VALUE(MID(R19,16,10))<TODAY(),"🟥 Obsoleto", IF(YEAR(VALUE(MID(R19,16,10)))=YEAR(TODAY()),"Actualizaciones disponibles", IF(YEAR(VALUE(MID(R19,16,10)))-YEAR(TODAY())=1,"Actualizaciones disponibles", IF(YEAR(VALUE(MID(R19,16,10)))-YEAR(TODAY())=2,"Actualizaciones disponibles", "Actualizaciones disponibles" ) ) ) ), "⛔ Sin datos" ), "⛔ Error en fecha" ) -> ⛔ Sin datos | T19: =IF(OR(S19 = "🟥 Obsoleto",S19 = "⛔ Sin datos"), "Ya no cuenta con actualizaciones", IFERROR( CONCATENATE( "E" & IFERROR(CHOOSE(MATCH(INDEX(ControlMensual!H:H, MATCH(F19, ControlMensual!B:B, 0)), {"ok";"no";"pendiente"}, 0),"✅","❌","🕓"), "⛔") & " ", "F" & IFERROR(CHOOSE(MATCH(INDEX(ControlMensual!I:I, MATCH(F19, ControlMensual!B:B, 0)), {"ok";"no";"pendiente"}, 0),"✅","❌","🕓"), "⛔") & " ", "M" & IFERROR(CHOOSE(MATCH(INDEX(ControlMensual!J:J, MATCH(F19, ControlMensual!B:B, 0)), {"ok";"no";"pendiente"}, 0),"✅","❌","🕓"), "⛔") & " ", "A" & IFERROR(CHOOSE(MATCH(INDEX(ControlMensual!K:K, MATCH(F19, ControlMensual!B:B, 0)), {"ok";"no";"pendiente"}, 0),"✅","❌","🕓"), "⛔") & " ", "M" & IFERROR(CHOOSE(MATCH(INDEX(ControlMensual!L:L, MATCH(F19, ControlMensual!B:B, 0)), {"ok";"no";"pendiente"}, 0),"✅","❌","🕓"), "⛔") & " ", "J" & IFERROR(CHOOSE(MATCH(INDEX(ControlMensual!M:M, MATCH(F19, ControlMensual!B:B, 0)), {"ok";"no";"pendiente"}, 0),"✅","❌","🕓"), "⛔") & " ", "J" & IFERROR(CHOOSE(MATCH(INDEX(ControlMensual!N:N, MATCH(F19, ControlMensual!B:B, 0)), {"ok";"no";"pendiente"}, 0),"✅","❌","🕓"), "⛔") & " ", "A" & IFERROR(CHOOSE(MATCH(INDEX(ControlMensual!O:O, MATCH(F19, ControlMensual!B:B, 0)), {"ok";"no";"pendiente"}, 0),"✅","❌","🕓"), "⛔") & " ", "S" & IFERROR(CHOOSE(MATCH(INDEX(ControlMensual!P:P, MATCH(F19, ControlMensual!B:B, 0)), {"ok";"no";"pendiente"}, 0),"✅","❌","🕓"), "⛔") & " ", "O" & IFERROR(CHOOSE(MATCH(INDEX(ControlMensual!Q:Q, MATCH(F19, ControlMensual!B:B, 0)), {"ok";"no";"pendiente"}, 0),"✅","❌","🕓"), "⛔") & " ", "N" & IFERROR(CHOOSE(MATCH(INDEX(ControlMensual!R:R, MATCH(F19, ControlMensual!B:B, 0)), {"ok";"no";"pendiente"}, 0),"✅","❌","🕓"), "⛔") & " ", "D" & IFERROR(CHOOSE(MATCH(INDEX(ControlMensual!S:S, MATCH(F19, ControlMensual!B:B, 0)), {"ok";"no";"pendiente"}, 0),"✅","❌","🕓"), "⛔") ) ,"") ) -> Ya no cuenta con actualizaciones | U19: Si | V19: Si | W19: No | X19: No aplica | Y19: =COUNTIF(U19:X19,"Si")/(COUNTIF(U19:X19,"Si")+COUNTIF(U19:X19,"No")) -> 0.66666667 | Z19: Migración FICO | AA19: 45930 | AB19: Sistemas Financieros | AC19: Claudia León | AD19: No | AE19: =VLOOKUP(E19,Falcon!B$2:C$558,2,FALSE) -> #REF! | AF19: =VLOOKUP(E19,VisionOne!B$2:C$229,2,FALSE) -> #REF! | AG19: =VLOOKUP(E19,Central!B$2:C$217,2,FALSE) -> #REF! | AH19: No | AJ19: Patricio Alegría | AK19: Si | AL19: x | AM19: =VLOOKUP(D19,'Copia de vInfo 2'!A:A,1,FALSE) -> #REF! | AN19: Sí
