Workbook

Sheet Iniciativas (2)
A1: INI | B1: Iniciativa | C1: Descripción | D1: Objetivos generales | E1: Orden de magnitud USD | F1: PILAR | G1: Tipo de cliente (flujo) | H1: Ámbito funcional/negocio/gobierno (conceptos) que priorizan el esfuerzo, luego lo técnico se alinea a esto | I1: Beneficios | J1: Detalle actividades | K1: Entregables | L1: Prerrequisitos INI / ALT | M1: Otros Prerrequisitos (no iniciativas) | N1: Prerrequisitos ACTUALIZADOS (ANTIGUO) | O1: Prerrequisitos y dependencia entre iniciativas (ANTIGUO) | P1: Plan de trabajo | Q1: Responsables | R1: Categoría | S1: Etapa del flujo | T1: Dominio | U1: estado PWC | V1: Etapa TO-BE (Imagen) | W1: Etapa Simplificada | X1: Justificación Mapeo | Y1: Pilar Aplicativo Principal | Z1: Pilar Aplicativo Secundario | AA1: Grupo Tecnológico | AB1: Capa de Arquitectura | AC1: Plataforma / Infra | AD1: Componentes Impactados | AE1: Servicios EAI | AF1: Notas Revisión Duplicidad | AG1: Estado Revisión
A2: INI-01 | B2: Pre-evaluación FICO para Cliente Sin Oferta en Campaña | C2: Nodo diferenciado de pre-evaluación con FICO para clientes sin oferta en campaña. Si FICO rechaza → Fin inmediato (ahorra recursos). Si aprueba → pasa a "Nuevo servicio" + Simulación. | D2: Implementar nodo diferenciado de pre-evaluación que filtre tempranamente clientes sin oferta → ahorra ~30-40% de evaluaciones innecesarias | E2: =SUMIF('Por actividad (2)'!A:A,'Iniciativas (2)'!A2,'Por actividad (2)'!N:N) -> 155636.77 | F2: Funcional/Negocio | G2: Cliente sin oferta aprobada | I2: B1: Ahorro de recursos (menos llamadas a servicios/motores posteriores y menos procesamiento) al cortar tempranamente los rechazados por FICO. B2: Mejor control de riesgo al aplicar un filtro estándar y consistente antes de ofertar dinámicamente. B3: Mejora la eficiencia del flujo al separar clientes “viables” vs “no viables” desde el inicio. B4: Mejor experiencia para no elegibles (respuesta rápida) y para elegibles (pasan a oferta + simulación sin pasos innecesarios). B5: Trazabilidad de decisiones (motivos FICO y derivación a siguiente etapa) para monitoreo y auditoría. | J2: A1: Definir el segmento “cliente sin oferta” y condiciones de entrada al nodo (qué casos aplican y cuáles no). A2: Definir reglas de decisión FICO (umbral(es), códigos de rechazo, vigencia, tratamiento de “sin score / error / data insuficiente”). A3: Diseñar el flujo de orquestación: FICO → (rechazo y fin) / (aprobación y derivación a INI-02 + simulación). A4: Implementar integración técnica con FICO (API, seguridad, timeouts, retries) + manejo de contingencias/fallback. A5: Implementar mensajería y motivos para canal (rechazo inmediato vs continúa) y registrar auditoría/logs. A6: Ejecutar pruebas y piloto (funcionales, performance, caída de servicios) y calibrar umbrales si corresponde. | K2: E1: Documento de alcance y requerimientos del nodo de pre-evaluación (incluye criterios “sin oferta”). E2: Diseño del flujo (diagrama del nodo FICO + derivación a INI-02 + simulación). E3: Política/parametría FICO: umbrales, tratamiento de excepciones (“no hit”, error, data incompleta) y motivos. E4: Catálogo de motivos/códigos para fin inmediato y para derivación (mensajes por canal). E5: Especificación de integración/API con FICO (contratos, seguridad, timeouts, reintentos). E6: Implementación del nodo en el orquestador/flujo (configuración por ambiente + feature flags si aplica). E7: Plan y evidencias de pruebas (unitarias, integración, E2E con INI-02, performance/contingencia) + UAT firmado. E8: Monitoreo/KPIs (tasa de rechazo FICO, latencia, errores, derivación a INI-02, ahorro estimado de llamadas) + alertas. E9: Informe de piloto/despliegue con resultados y ajustes recomendados. | L2: INI-02, INI-04, INI-05, INI-07, INI-09, INI-12, INI-18, INI-20 | M2: accesos/conectividad a ambientes FICO, definición de umbrales/reglas y manejo de excepciones por Riesgo (no-hit/error/data insuficiente) y trazabilidad/auditoría | N2: Requiere accesos/conectividad a ambientes FICO, definición de umbrales/reglas y manejo de excepciones por Riesgo (no-hit/error/data insuficiente) y trazabilidad/auditoría; depende de INI-12 y se integra con INI-05 (ruteo “Sin oferta”), INI-02 (si aprueba pasa a oferta dinámica), INI-07 (persistencia/retoma), INI-04 (doc antes de curse) y medición INI-09/INI-09 (ex INI-10). 🔗 DEPENDENCIAS CRUZADAS (Func↔Téc): INI-18 (FICO v7 estable para pre-evaluación); INI-29 (Gobierno E2E técnico); INI-20 (Precálculo oferta viable). | O2: Requiere accesos/conectividad a ambientes FICO, definición de umbrales/reglas y manejo de excepciones por Riesgo (no-hit/error/data insuficiente) y trazabilidad/auditoría; depende de INI-12 y se integra con INI-05 (ruteo “Sin oferta”), INI-02 (si aprueba pasa a oferta dinámica), INI-07 (persistencia/retoma), INI-04 (doc antes de curse) y medición INI-09/INI-09 (ex INI-10). | P2: PENDIENTE EN CASO DE PRIORIZACIÓN | Q2: Ger. Riesgo, Ger. Comercial/Producto, Proveedor FICO/Ventiv, TI Integración/Arquitectura, Sonda (infra/OCI-OKE), Canales (TAPP/SVP), Operaciones | R2: Funcional | S2: Generación de Oferta | T2: 🔴 Riesgo | V2: Generación de Oferta | W2: Generación de Oferta | X2: Pre-evaluación FICO para cliente sin oferta → nodo antes de simulación | Y2: Motor FICO (DMPS/Blaze) | Z2: Base Aprobados, MenuAndes | AA2: Motor de Decisión | AB2: Lógica de Negocio | AC2: OCI Santiago → OCI/OKE | AD2: FICO DMPS, Blaze v4/v7, Orquestador Gateway | AE2: — | AG2: Sin cambios
A3: INI-02 | B3: Nuevo Servicio de Generación de Oferta Dinámica - | C3: Servicio post pre-evaluación que genera oferta dinámica para clientes sin oferta pre-aprobada. Hoy estos clientes van directo al motor o son rechazados. | D3: Diseñar, construir e implementar un servicio post pre-evaluación que genere una oferta dinámica para clientes que no cuentan con oferta pre-aprobada, de modo que en lugar de enviarlos directamente al motor o rechazarlos, se les presente una alternativa de oferta (monto/plazo/tasa/condiciones) acorde a su perfil de riesgo y políticas vigentes, mejorando conversión sin deteriorar el riesgo. | E3: =SUMIF('Por actividad (2)'!A:A,'Iniciativas (2)'!A3,'Por actividad (2)'!N:N) -> 104192.83 | F3: Funcional/Negocio | G3: Cliente sin oferta aprobada | I3: B1: Aumenta la conversión/originación al capturar clientes que hoy quedan sin oferta o rechazados. B2: Mejora la experiencia del cliente al entregar alternativas en vez de un rechazo inmediato. B3: Permite gestionar apetito de riesgo con parámetros (límites, pricing, reglas) ajustables. B4: Reduce derivaciones y fricción operativa (menos re-trabajo y reintentos). B5: Entrega trazabilidad y control (motivos, auditoría, versionado de reglas) para riesgo y compliance. | J3: A1: Levantar flujo actual y definir casos de uso para clientes sin pre-aprobación (ofertar / pedir datos / no ofertar). A2: Definir políticas y reglas de elegibilidad + parámetros de oferta (monto/plazo/tasa/condiciones) y “motivos de no oferta”. A3: Diseñar el modelo de generación de oferta (segmentación por riesgo/score, matriz de oferta, 1 vs N ofertas). A4: Diseñar e implementar el servicio/API e integraciones (pre-evaluación, datos internos/externos, pricing, motor si aplica) + auditoría. A5: Ejecutar pruebas y calibración (funcionales, integración, performance) con histórico/simulación y ajustes de parámetros. A6: Implementar piloto y despliegue gradual por canal/segmento, con monitoreo de KPIs y mejora continua. | K3: E1: Documento de requerimientos y alcance (funcional / no funcional). E2: Diseño de proceso/journey objetivo (sin pre-aprobación → oferta dinámica → siguiente paso). E3: Reglas de elegibilidad + matriz/estrategia de oferta (parámetros por segmento/score) y versionado. E4: Catálogo de motivos/códigos (no oferta, rechazo, derivación) y mensajes para canal. E5: Especificación de API (OpenAPI) + arquitectura e integraciones + lineamientos de auditoría/logging. E6: Implementación del servicio (código + configuración por ambiente / feature flags). E7: Plan y evidencias de pruebas (unitarias, integración, E2E, performance) + UAT firmado. E8: Tablero de monitoreo (conversión, % con oferta, aceptación, latencia/errores, mora temprana si aplica) + alertas. E9: Informe de piloto/despliegue con resultados, ajustes y recomendación de escalamiento. | L3: INI-01, INI-04, INI-07, INI-09, INI-11, INI-12, INI-18, INI-20 | M3: definición de política/matriz de oferta dinámica (monto/plazo/tasa/condiciones), fuentes de datos y catálogo de motivos/auditoría; y normalmente de , se apalanca opcionalmente en , y se integra con , y medición | N3: Requiere definición de política/matriz de oferta dinámica (monto/plazo/tasa/condiciones), fuentes de datos y catálogo de motivos/auditoría; depende de INI-12 y normalmente de INI-01 (gate pre-FICO en “Sin oferta”), se apalanca opcionalmente en INI-11 (parametrización de reglas), y se integra con INI-07, INI-04 y medición INI-09/INI-09 (ex INI-10). 🔗 DEPENDENCIAS CRUZADAS (Func↔Téc): INI-18 (FICO v7 para evaluación); INI-20 (Precálculo como base de oferta). | O3: Requiere definición de política/matriz de oferta dinámica (monto/plazo/tasa/condiciones), fuentes de datos y catálogo de motivos/auditoría; depende de INI-12 y normalmente de INI-01 (gate pre-FICO en “Sin oferta”), se apalanca opcionalmente en INI-11 (parametrización de reglas), y se integra con INI-07, INI-04 y medición INI-09/INI-09 (ex INI-10). | P3: PENDIENTE EN CASO DE PRIORIZACIÓN | Q3: Ger. Comercial/Producto, Ger. Riesgo (políticas/umbrales), TI Arquitectura/Integración, Proveedor FICO/Ventiv (si participa en decisión/scoring), Canales (TAPP/SVP/Sucursal), Data/BI (seguimiento) | R3: Funcional | S3: Generación de Oferta | T3: 🟢 Producto🔴 Riesgo | V3: Generación de Oferta | W3: Generación de Oferta | X3: Oferta dinámica post pre-evaluación → genera oferta viable | Y3: Motor FICO (DMPS/Blaze) | Z3: FlexCube, MenuAndes | AA3: Motor de Decisión | AB3: Lógica de Negocio | AC3: GCP (nuevo servicio) | AD3: Nuevo Servicio Oferta Dinámica, FICO, FlexCube | AE3: — | AG3: Sin cambios
A4: INI-03 | B4: Flujo aprobado express | C4: Camino directo para "Aprobados Express": Paquete oferta → Simulación → (sin evaluación FICO) → Documentación → Curse. Bypass del motor para clientes de buen comportamiento. (2 OPCIONES) | D4: Implementar un camino “Fast Track Express” que permita a clientes identificados como Aprobados Express (por buen comportamiento y criterios definidos) avanzar desde paquete de oferta → simulación → documentación → curse, sin pasar por la evaluación FICO / motor tradicional, manteniendo controles mínimos de riesgo, fraude y cumplimiento para reducir tiempos y fricción sin deteriorar calidad de cartera. | E4: =SUMIF('Por actividad (2)'!A:A,'Iniciativas (2)'!A4,'Por actividad (2)'!N:N) -> 109578.48 | F4: Funcional/Negocio | G4: Cliente oferta aprobada express | I4: B1: Aumenta la conversión al reducir pasos y fricción del proceso estándar. B2: Disminuye el time-to-yes / time-to-cash (aprobación y desembolso más rápidos). B3: Reduce costo operativo (menos validaciones redundantes, menos re-trabajo). B4: Mejora la experiencia y fidelización de clientes de buen comportamiento. B5: Mantiene control y trazabilidad (reglas claras, auditoría, límites y derivación a flujo estándar cuando aplique). | J4: A1: Definir criterios “Aprobado Express” (elegibilidad, exclusiones, vigencia, límites por monto/plazo). A2: Diseñar el flujo Fast Track y puntos de decisión (Express vs derivación a flujo estándar). A3: Acordar e implementar controles mínimos (KYC/AML, identidad, antifraude, políticas internas) para permitir el bypass. A4: Definir e implementar paquete de oferta + simulación (condiciones, vigencia, validaciones de límites). A5: Implementar servicios/APIs e integraciones (canales, data comportamiento, KYC/AML, documental, curse) + manejo de errores/fallback. A6: Ejecutar pruebas y piloto (UAT, performance, seguridad), monitoreo de KPIs y calibración de reglas. | K4: E1: Documento de política Express: criterios, exclusiones, vigencia, límites y gobierno de cambios. E2: Diseño del proceso Fast Track (diagrama de flujo + derivación a estándar + mensajes/motivos). E3: Matriz de controles mínimos (riesgo/fraude/compliance) + “stop conditions”. E4: Definición del paquete de oferta y reglas de simulación (parámetros, vigencia, restricciones). E5: Especificación técnica/API (OpenAPI) + arquitectura e integraciones. E6: Implementación (servicios, configuración de reglas, feature flags). E7: Plan y evidencias de pruebas (unitarias, integración, E2E, performance, seguridad) + UAT firmado. E8: Tablero de monitoreo (KPIs operativos y de riesgo) + alertas. E9: Informe de piloto y versión final calibrada (recomendaciones y parámetros finales). | L4: INI-04, INI-05, INI-07, INI-09, INI-11, INI-12, INI-34 | M4: criterios “Aprobado Express”, límites/exclusiones y controles mínimos KYC/AML/antifraude definidos por Riesgo/Compliance y trazabilidad; y de , se integra con y , se mide con y puede apalancarse en para parametría | N4: Requiere criterios “Aprobado Express”, límites/exclusiones y controles mínimos KYC/AML/antifraude definidos por Riesgo/Compliance y trazabilidad; depende de INI-12 y de INI-05 (clasificación Express), se integra con INI-04 (doc) y INI-07 (retoma), se mide con INI-09/INI-09 (ex INI-10) y puede apalancarse en INI-11 para parametría. 🔗 DEPENDENCIAS CRUZADAS (Func↔Téc): INI-34 (BD Corporativa para datos de cliente express); INI-29 (Gobierno E2E). | O4: Requiere criterios “Aprobado Express”, límites/exclusiones y controles mínimos KYC/AML/antifraude definidos por Riesgo/Compliance y trazabilidad; depende de INI-12 y de INI-05 (clasificación Express), se integra con INI-04 (doc) y INI-07 (retoma), se mide con INI-09/INI-09 (ex INI-10) y puede apalancarse en INI-11 para parametría. | P4: PENDIENTE EN CASO DE PRIORIZACIÓN | Q4: Ger. Riesgo, Ger. Comercial/Producto, Canales Digitales (TAPP/SVP), TI Arquitectura/Integración, Proveedor FICO/Ventiv (para definir bypass/control mínimo), Compliance/Seguridad | R4: Funcional | S4: Simulación → Curse | T4: 🔴 Riesgo🟡 Canal | V4: Evaluación → Documentación (Bypass) | W4: Evaluación (Bypass → Documentación) | X4: Fast Track: Express salta Evaluación FICO, va directo Simulación → Documentación | Y4: Motor FICO (DMPS/Blaze) | Z4: Siebel, TAPP, Base Aprobados | AA4: Motor de Decisión | AB4: Lógica de Negocio + Canal | AC4: OCI + GCP | AD4: Blaze Advisor (bypass rules), Siebel, TAPP BFF | AE4: — | AG4: Sin cambios
A5: INI-04 | B5: Orquestación Documentación Digital - | C5: Etapa explícita de "Generación, firma y Control doc." previa al curse. Hoy la documentación y firma están fuera del proceso de onboarding — el flujo la integra. | D5: Implementar e integrar en el onboarding una etapa explícita y orquestada de “Generación, firma y control documental” previa al curse, incorporando la documentación y firma digital dentro del flujo end-to-end para asegurar completitud, trazabilidad y cumplimiento, reduciendo fricción operativa y reprocesos. | E5: =SUMIF('Por actividad (2)'!A:A,'Iniciativas (2)'!A5,'Por actividad (2)'!N:N) -> 60430.493 | F5: Funcional/Negocio | G5: Transversal (Express + Normal + Sin oferta) | I5: B1: Asegura cumplimiento y control: documentos correctos, firmados y validados antes del curse. B2: Reduce reprocesos y errores (documentación incompleta/faltante) al estandarizar la etapa. B3: Mejora tiempos de cierre/curse al automatizar generación, firma y verificación. B4: Entrega trazabilidad/auditoría end-to-end (qué se generó, quién firmó, cuándo, estado y evidencias). B5: Habilita una experiencia digital y omnicanal consistente (mismo flujo para web/app/sucursal/call center, según aplique). | J5: A1: Levantar el proceso actual y definir el alcance documental por producto/canal (qué documentos, cuándo aplican). A2: Definir la orquestación de estados: generar → enviar → firmar → validar → almacenar → habilitar curse (y qué pasa si falla). A3: Diseñar plantillas y parametría (variables, versiones, idioma, condiciones, anexos) y reglas de selección de documentos. A4: Integrar con servicios de firma digital y gestión documental (repositorio, evidencias, sellado de tiempo si aplica). A5: Implementar controles: completitud, consistencia de datos, validación de identidad/consentimiento, reintentos y vencimientos. A6: Pruebas end-to-end + piloto: generación masiva, firma, trazabilidad, contingencias (firma caída / cliente no firma / expiración). | K5: E1: Documento de alcance y catálogo documental (por producto/canal/segmento) + reglas de aplicabilidad. E2: Diseño del flujo de orquestación (estados, transiciones, errores, SLAs, reintentos, vencimientos). E3: Modelo de datos documental (metadatos, versionado, evidencias, auditoría). E4: Plantillas de documentos parametrizadas + matriz de selección (qué se genera en cada caso). E5: Especificación de integraciones/APIs (firma digital, repositorio documental, onboarding/orquestador, curse). E6: Implementación de la etapa documental (servicios, colas/eventos si aplica, configuración por ambiente). E7: Catálogo de motivos/códigos de estado documental (pendiente firma, rechazado, expirado, validación fallida, etc.). E8: Plan y evidencias de pruebas (funcionales, seguridad, performance, contingencias) + UAT firmado. E9: Tablero de monitoreo/KPIs (tasa de firma, tiempos por etapa, caídas, reprocesos, % curse habilitado) + alertas. | L5: INI-12, INI-21, INI-24 | M5: set documental por producto/canal, proveedor de firma digital, repositorio documental/evidencias y aprobaciones Legal/Compliance; y es transversal como paso previo a curse para rutas que cursan (Express/Normal/Sin oferta) | N5: Requiere set documental por producto/canal, proveedor de firma digital, repositorio documental/evidencias y aprobaciones Legal/Compliance; depende de INI-12 y es transversal como paso previo a curse para rutas que cursan (Express/Normal/Sin oferta). 🔗 DEPENDENCIAS CRUZADAS (Func↔Téc): INI-24 (Camel orquestador para flujo documentación); INI-21 (MS Lógica Crédito reemplaza Svc 147). | O5: Requiere set documental por producto/canal, proveedor de firma digital, repositorio documental/evidencias y aprobaciones Legal/Compliance; depende de INI-12 y es transversal como paso previo a curse para rutas que cursan (Express/Normal/Sin oferta). | P5: PENDIENTE EN CASO DE PRIORIZACIÓN | Q5: Operaciones (BackOffice/Admisión), Legal/Compliance, Proveedor Firma Digital/ECM (si existe), TI Integración/Arquitectura, Canales (TAPP/SVP/Sucursal) | R5: Funcional | S5: Documentación | T5: 🟡 Canal | V5: Documentación | W5: Documentación | X5: Orquestación de generación, firma y control documental | Y5: Siebel / Salesforce | Z5: FlexCube, eSign, BI Publisher | AA5: CRM + Documental | AB5: Proceso de Negocio | AC5: OCI Santiago | AD5: Siebel CRM, FlexCube, eSign, BI Publisher | AE5: — | AG5: Sin cambios
A6: INI-05 | B6: Segmentación de Campaña No Cliente | C6: Punto de decisión inteligente al inicio que clasifica: Express / Normal / Sin oferta / NO OK. Hoy Siebel lo hace parcialmente. En TO-BE debería ser un microservicio. | D6: Diseñar e implementar un microservicio de derivación al inicio del onboarding que clasifique inteligentemente a cada cliente en Express / Normal / Sin oferta / NO OK, sustituyendo o complementando la clasificación parcial actual de Siebel, para enrutar al flujo TO-BE correcto con consistencia, trazabilidad y control (incluyendo criterios de elegibilidad y exclusión). | E6: =SUMIF('Por actividad (2)'!A:A,'Iniciativas (2)'!A6,'Por actividad (2)'!N:N) -> 71089.686 | F6: Funcional/Negocio | G6: Transversal (Express + Normal + Sin oferta + No ok) | I6: B1: Reduce fricción y mejora conversión al enrutar correctamente desde el inicio (menos desvíos y re-trabajo). B2: Aumenta la eficiencia operativa y tecnológica (menos lógica dispersa en canales/Siebel, menor complejidad). B3: Mejora el control de riesgo/compliance con criterios centralizados (incluye “NO OK” temprano). B4: Entrega consistencia omnicanal (misma clasificación para web/app/sucursal/call center). B5: Habilita evolución rápida (reglas parametrizables, versionado, feature flags) sin cambios grandes en canales. B6: Provee trazabilidad/auditoría (por qué fue Express/Normal/Sin oferta/NO OK, con variables y reglas aplicadas). | J6: A1: Definir la taxonomía y criterios de cada tipo: Express / Normal / Sin oferta / NO OK (reglas y exclusiones). A2: Levantar la lógica actual en Siebel y diseñar el TO-BE (qué se migra, qué se elimina, qué queda temporalmente). A3: Diseñar el microservicio: API, entradas/salidas, performance, seguridad, idempotencia y manejo de errores. A4: Definir e integrar fuentes de datos necesarias (CRM/Siebel, comportamiento, KYC/AML, antifraude, ofertas, etc.). A5: Implementar motor de reglas parametrizable + versionado + auditoría (logs, motivos, rule-id). A6: Pruebas + piloto: exactitud de clasificación, latencia, contingencias (data faltante/servicios caídos) y calibración. | K6: E1: Documento de alcance y criterios de clasificación (reglas por tipo, exclusiones, prioridades). E2: Diseño TO-BE de enrutamiento (diagrama end-to-end: punto de decisión → flujos INI-01/02/03/04/normal). E3: Contrato de API del microservicio (OpenAPI) + modelo de datos (request/response). E4: Matriz de fuentes de datos e integraciones (qué se consulta, para qué, SLA/timeout). E5: Catálogo de motivos/códigos de clasificación (Express/Normal/Sin oferta/NO OK) y mensajes por canal. E6: Implementación del microservicio (reglas parametrizables, versionado, feature flags). E7: Plan y evidencias de pruebas (unitarias, integración, performance, resiliencia) + UAT firmado. E8: Tablero de monitoreo/KPIs (distribución por tipo, latencia, errores, derivaciones, precisión vs Siebel) + alertas. E9: Plan de migración desde Siebel (coexistencia, corte, rollback) + reporte de piloto/despliegue. | L6: INI-01, INI-02, INI-03, INI-09, INI-11, INI-12, INI-22 | M6: definición unívoca de tipología Express/Normal/Sin oferta/NO OK, señales de clasificación (incluyendo qué se consulta vía FICO y qué se toma de Siebel en presencial), API con performance y auditoría; se apalanca opcionalmente en , y habilita ruteo hacia y hacia /; su efectividad se mide con | N6: Requiere definición unívoca de tipología Express/Normal/Sin oferta/NO OK, señales de clasificación (incluyendo qué se consulta vía FICO y qué se toma de Siebel en presencial), API con performance y auditoría; depende de INI-12, se apalanca opcionalmente en INI-11, y habilita ruteo hacia INI-03 y hacia INI-01/INI-02; su efectividad se mide con INI-09/INI-09 (ex INI-10). 🔗 DEPENDENCIAS CRUZADAS (Func↔Téc): INI-22 (Apigee para convergencia canales); INI-29 (Gobierno E2E). | O6: Requiere definición unívoca de tipología Express/Normal/Sin oferta/NO OK, señales de clasificación (incluyendo qué se consulta vía FICO y qué se toma de Siebel en presencial), API con performance y auditoría; depende de INI-12, se apalanca opcionalmente en INI-11, y habilita ruteo hacia INI-03 y hacia INI-01/INI-02; su efectividad se mide con INI-09/INI-09 (ex INI-10). | P6: PENDIENTE EN CASO DE PRIORIZACIÓN | Q6: TI Arquitectura/Integración (owner técnico), Ger. Riesgo (reglas de clasificación), Ger. Comercial/Producto, Canales (TAPP/SVP), Equipo Siebel (Sucursal Presencial), Proveedor FICO/Ventiv (si es fuente de señales) | R6: Funcional | S6: Punto de Entrada | T6: 🟣 Cliente🔴 Riesgo | V6: Punto de Entrada | W6: Punto de Entrada | X6: Segmentación campaña No Cliente → define tipo de cliente antes del flujo | Y6: Siebel / Salesforce | Z6: TAPP, Base Aprobados | AA6: CRM + Canal | AB6: Lógica de Negocio | AC6: OCI + GCP | AD6: Siebel (segmentación), TAPP, Base Aprobados | AE6: — | AG6: Sin cambios
A7: INI-06 | B7: Ajuste del Proceso de Derivación de Canales | C7: TAPP opera con modelo binario: aprueba o rechaza. 277.407 solicitudes/mes que en sucursal podrían haberse trabajado se pierden porque el digital no puede derivar a analista. | D7: Habilitar en el canal digital un mecanismo de derivación a gestión humana (analista/sucursal/contact center) para solicitudes que hoy quedan en un modelo binario (aprueba/rechaza), permitiendo rescatar oportunidades y trabajar casos “recuperables” mediante un handoff orquestado, con colas, SLA, trazabilidad y retroalimentación al flujo digital. | E7: =SUMIF('Por actividad (2)'!A:A,'Iniciativas (2)'!A7,'Por actividad (2)'!N:N) -> 62013.453 | F7: Funcional/Negocio | G7: Cliente no ok | I7: B1: Recupera solicitudes perdidas en digital al habilitar tratamiento humano (ej. parte de las 277.407 solicitudes/mes). B2: Incrementa conversión/originación al re-trabajar casos no aprobados automáticamente pero potencialmente viables. B3: Mejora la experiencia del cliente (no termina en rechazo definitivo; se ofrece alternativa/seguimiento). B4: Reduce abandono al dar continuidad (“te contactaremos / agenda / derivación a sucursal”). B5: Aumenta control y trazabilidad (motivos de derivación, tiempos, resultado, auditoría). B6: Permite optimizar reglas del motor digital con aprendizaje (insights sobre qué casos se recuperan). | J7: A1: Definir casos de derivación y criterios (qué se deriva vs qué se rechaza definitivo; motivos y priorización). A2: Diseñar el modelo operativo: quién atiende (analista/call center/sucursal), colas, SLA, horarios, capacidad y escalamiento. A3: Diseñar el handoff digital: captura mínima de datos, consentimiento, agendamiento/contactabilidad, estado visible al cliente. A4: Implementar la gestión de casos (creación de caso/ticket/lead en CRM o herramienta), asignación y trazabilidad end-to-end. A5: Integrar notificaciones y estados: actualizaciones al canal digital (en revisión, solicitado documento, aprobado, rechazado). A6: Piloto y calibración: medir recuperación, tiempos y causas; ajustar reglas de derivación y dotación. | K7: E1: Documento de alcance y reglas de derivación (criterios, exclusiones, motivos/códigos, priorización). E2: Diseño del proceso operativo (colas, SLA, roles, RACI, capacidad, escalamiento). E3: Journey/UX del cliente en digital para derivación (mensajes, consentimiento, agendamiento, tracking de estado). E4: Modelo de caso y datos mínimos (campos, adjuntos, estados, trazabilidad, auditoría). E5: Especificación de integraciones/APIs (digital ↔ CRM/case management ↔ notificaciones ↔ repositorios si aplica). E6: Implementación de creación/asignación de casos + bandeja/cola para analistas (o configuración si es herramienta existente). E7: Catálogo de estados y motivos (derivado, pendiente contacto, requiere docs, aprobado, rechazado) + plantillas de comunicación. E8: Plan y evidencias de pruebas (E2E, SLA, seguridad/PII, contingencias) + UAT firmado. E9: Tablero de KPIs (tasa de derivación, tasa de recuperación, TAT, contactabilidad, conversión, causas) + reporte de piloto. | L7: INI-07, INI-09, INI-12, INI-13, INI-22, INI-27 | M7: modelo operativo de atención humana (roles, colas, SLA, capacidad), herramienta de casos (posiblemente Siebel u otra) y consentimientos/contactabilidad; se apalanca en , se mide con (reconversión) y funciona como fallback junto con | N7: Requiere modelo operativo de atención humana (roles, colas, SLA, capacidad), herramienta de casos (posiblemente Siebel u otra) y consentimientos/contactabilidad; depende de INI-12, se apalanca en INI-07 (handoff con contexto/retoma), se mide con INI-09 (ex INI-10) (reconversión) y funciona como fallback junto con INI-13. 🔗 DEPENDENCIAS CRUZADAS (Func↔Téc): INI-22 (Apigee para derivación entre canales); INI-27 (Observabilidad para medir reconversión). | O7: Requiere modelo operativo de atención humana (roles, colas, SLA, capacidad), herramienta de casos (posiblemente Siebel u otra) y consentimientos/contactabilidad; depende de INI-12, se apalanca en INI-07 (handoff con contexto/retoma), se mide con INI-09 (ex INI-10) (reconversión) y funciona como fallback junto con INI-13. | P7: PENDIENTE EN CASO DE PRIORIZACIÓN | Q7: Operaciones/Admisión (dueño del proceso y SLAs), Canales Digitales (TAPP/SVP), Ger. Sucursal Presencial (si recibe derivaciones), Equipo Siebel/CRM, Ger. Comercial, Data/BI (medición de recuperación) | R7: Funcional | S7: FG-19 | T7: 🟡 Canal📊 Negocio | V7: Evaluación → Simulación (Derivación) | W7: Simulación + Evaluación | X7: FG-19: Derivación a atención humana cuando TAPP rechaza. Aplica en decisión post-evaluación | Y7: TAPP (Canal Digital) | Z7: Siebel, BFF, Kafka | AA7: Canal Digital | AB7: Canal + Proceso | AC7: GCP (GKE) | AD7: TAPP, BFF, Kafka, Siebel (derivación) | AE7: — | AG7: Sin cambios
A8: INI-07 | B8: Retomabilidad Omnicanal (Persistencia de Estado) - digital y presencial | C8: Un cliente que inicia en digital y no completa, hoy reinicia desde cero en sucursal. El flujo requiere que el estado se persista entre Simulación y Evaluación para retomar en otro canal. [PASO 1 — Base Técnica Compartida] Esta iniciativa construye la capa de persistencia de estado que es PRERREQUISITO para INI-15 (Session Recovery ante caída) e INI-16 (Notificación post-caída). El servicio de persistencia que aquí se desarrolla es reutilizado por ambas iniciativas dependientes. | D8: Implementar persistencia de estado y retomabilidad omnicanal para que un cliente que inicia el onboarding en un canal (p. ej. digital) y no completa, pueda retomar el proceso en otro canal (p. ej. sucursal) sin reiniciar desde cero, persistiendo especialmente el estado y datos clave entre Simulación y Evaluación (y, idealmente, hasta Documentación), con trazabilidad, vigencia y controles de seguridad/consentimiento. | E8: =SUMIF('Por actividad (2)'!A:A,'Iniciativas (2)'!A8,'Por actividad (2)'!N:N) -> 78654.709 | F8: Funcional/Negocio | G8: Transversal (Express + Normal + Sin oferta) | I8: B1: Incrementa conversión al reducir abandono por tener que reiniciar el flujo en otro canal. B2: Mejora la experiencia omnicanal (continuidad y consistencia de la solicitud). B3: Reduce tiempos y fricción en sucursal/call center (menos captura repetida). B4: Disminuye errores de data por reingreso manual y mejora calidad de información. B5: Aporta trazabilidad del journey (qué se hizo, dónde se quedó, qué falta). B6: Habilita analítica de funnel real omnicanal (abandono, retomabilidad, cuellos de botella). | J8: A1: Definir el alcance de estado a persistir (datos mínimos, decisiones, oferta simulada, documentos pendientes) y en qué hitos (Simulación/Evaluación/Doc). A2: Definir identificador de continuidad (ID solicitud) y reglas de vinculación cliente-solicitud (login, OTP, documento, etc.). A3: Diseñar la arquitectura de persistencia (store de estado, modelo de datos, APIs de lectura/escritura, versionado). A4: Definir vigencias y caducidades (TTL de simulación/oferta, refresh de datos, re-evaluación si expira). A5: Integrar canales y backends para guardar/recuperar estado (digital, sucursal, CRM/Siebel, orquestador, motor/FICO si aplica). A6: Pruebas end-to-end omnicanal + piloto (casos de retoma, expiración, concurrencia, seguridad). | K8: E1: Documento de alcance funcional de retomabilidad (hitos, casos de uso, qué se persiste y qué no). E2: Modelo de datos de estado (campos, estructura, versionado, evidencias y auditoría). E3: Definición de ID de solicitud y reglas de reconciliación (cómo se “encuentra” la solicitud en otro canal). E4: Especificación de APIs de persistencia/retoma (crear, actualizar, consultar, reanudar, cerrar/cancelar). E5: Política de vigencia/expiración (TTL, revalidaciones, cuándo se fuerza nueva evaluación). E6: Implementación del servicio/store de estado + integraciones con canales y orquestador. E7: Journey omnicanal (mensajes al cliente y al ejecutivo: “solicitud en curso”, “pendiente”, “expirada”). E8: Plan y evidencias de pruebas (E2E omnicanal, concurrencia, seguridad/PII, contingencias) + UAT firmado. E9: Monitoreo/KPIs (tasa de retoma, conversión post-retoma, abandono por etapa, tiempos entre canales) + reporte de piloto. | L8: INI-06, INI-09, INI-12, INI-13, INI-15, INI-25, INI-34 | M8: ID único de solicitud, store de estado seguro (PII), TTL/vigencias y definición de qué se persiste entre Simulación↔Evaluación para TAPP/SVP/Presencial (Siebel); habilita (reconversión), potencia , se complementa con y soporta continuidad en | N8: Requiere ID único de solicitud, store de estado seguro (PII), TTL/vigencias y definición de qué se persiste entre Simulación↔Evaluación para TAPP/SVP/Presencial (Siebel); depende de INI-12, habilita INI-09 (ex INI-10) (reconversión), potencia INI-06 (derivación con contexto), se complementa con INI-15 (recovery fino) y soporta continuidad en INI-13. 🔗 DEPENDENCIAS CRUZADAS (Func↔Téc): INI-25 (Redis caché para persistir estado); INI-34 (BD Corporativa para datos unificados). | O8: Requiere ID único de solicitud, store de estado seguro (PII), TTL/vigencias y definición de qué se persiste entre Simulación↔Evaluación para TAPP/SVP/Presencial (Siebel); depende de INI-12, habilita INI-09 (ex INI-10) (reconversión), potencia INI-06 (derivación con contexto), se complementa con INI-15 (recovery fino) y soporta continuidad en INI-13. | P8: PENDIENTE EN CASO DE PRIORIZACIÓN | Q8: TI Arquitectura/Integración (owner), Canales (TAPP/SVP), Ger. Sucursal Presencial + Equipo Siebel, Seguridad/Ciber (PII/controles), Operaciones, Data/BI | R8: Funcional | S8: FG-19 FG-36 | T8: 🟡 Canal🟣 Cliente | V8: Simulación → Evaluación (Transversal) | W8: Simulación + Evaluación | X8: FG-19/FG-36: Persistencia de estado entre Simulación y Evaluación para retomar en otro canal | Y8: TAPP (Canal Digital) | Z8: Siebel, Redis (caché estado) | AA8: Canal Digital + Integración | AB8: Canal + Datos | AC8: GCP + OCI | AD8: TAPP, Siebel, Redis, MS Estado (nuevo) | AE8: — | AF8: 🟡 PASO 1: Construye la capa base de persistencia de estado. Prerrequisito de INI-15 e INI-16. | AG8: Paso 1 declarado
A9: INI-09 | B9: Seguimiento y Trazabilidad de Data para Información de Negocio | C9: El flujo tiene 5 etapas claras, pero hoy no existen métricas de funnel ni instrumentación para medir abandono, reconversión o conversión por etapa/canal. De 565.297 pre-evaluaciones solo 28.280 se convierten en ventas (5%). No se sabe cuántos clientes abandonan en cada nodo digital ni si retoman en sucursal. Esta iniciativa unifica el seguimiento de data E2E (funnel de conversión + trazabilidad de abandono + reconversión omnicanal) en una sola macro-iniciativa, habilitando la información de negocio necesaria para tomar decisiones basadas en datos. | D9: Diseñar e implementar una plataforma de seguimiento y trazabilidad de data end-to-end que: (1) mida la conversión por etapa del flujo (5 etapas) y por canal (TAPP, SVP, Sucursal Presencial); (2) instrumente el abandono en cada nodo del flujo digital y la reconversión/retoma en Sucursal Presencial; (3) identifique el impacto del 'No' en Simulación y Evaluación (rechazo vs abandono vs caída técnica); (4) habilite visibilidad, gestión del desempeño y acciones de recuperación basadas en datos, mejorando la conversión actual (565.297 pre-evaluaciones → 28.280 ventas = 5%) y la información disponible para negocio. | E9: =SUMIF('Por actividad (2)'!A:A,'Iniciativas (2)'!A9,'Por actividad (2)'!N:N) -> 131116.59 | F9: Funcional/Negocio | G9: Transversal (todos los flujos) | I9: B1: Visibilidad de dónde se cae la conversión (por etapa, canal, producto y motivo). B2: Cuantifica el abandono real por nodo digital (dónde se pierden clientes y en qué magnitud). B3: Mide la reconversión omnicanal: cuántos abandonan digital y terminan vendiendo en sucursal (atribución). B4: Permite entender el impacto del 'No' en Simulación/Evaluación (rechazo vs abandono vs derivación). B5: Permite priorizar iniciativas con impacto real (optimización basada en datos, no percepciones). B6: Habilita acciones de recuperación (contacto, derivación, recordatorios, ofertas alternativas) basadas en triggers. B7: Mejora la gestión operativa con alertas y seguimiento de SLAs (tiempos por etapa, colas, caídas técnicas). B8: Habilita comparabilidad omnicanal (TAPP vs SVP vs Presencial) y detección de brechas de experiencia. B9: Reduce 'caja negra' de decisiones al incorporar motivos/códigos estandarizados. B10: Soporta gobierno y mejora continua (A/B tests, calibración de reglas, seguimiento post-cambios). | J9: A1: Definir el modelo de funnel: etapas estándar, eventos de entrada/salida y transiciones obligatorias (incluye abandonos y rechazos). A2: Definir diccionario de métricas y KPIs (conversión etapa-etapa, tasa de caída, TAT por etapa, tasa de error, % derivación, abandono por nodo). A3: Acordar el identificador único de solicitud y reglas para deduplicación/omnichannel (una solicitud que migra de canal). A4: Definir qué es 'abandono' por nodo digital (timeout, cierre app, drop-off, 'No', error) y el modelo de eventos (start/finish/decision/error) + motivos/códigos. A5: Instrumentar eventos en sistemas/canales (TAPP, SVP, Presencial/orquestador, FICO, documental, curse) con códigos de estado/motivo. A6: Integrar con datos de Sucursal Presencial para detectar retoma/venta posterior y construir atribución omnicanal. A7: Implementar pipeline de datos (ingesta, calidad, reconciliación, dimensiones: canal/etapa/producto/segmento) y almacenamiento. A8: Construir dashboards y alertas (funnel de conversión + abandono por nodo + reconversión); ejecutar piloto de medición, ajustar definiciones y cerrar gobierno de datos. | K9: E1: Definición del funnel TO-BE (5 etapas) con mapa de eventos y transiciones por canal. E2: Definición de abandono por nodo (criterios, ventanas de tiempo, reglas de conteo) y mapa de nodos digitales. E3: Diccionario de métricas/KPIs unificado (funnel + abandono + reconversión: fórmulas, ventanas, segmentaciones, ownership). E4: Definición del ID único de solicitud + reglas de deduplicación y continuidad omnicanal (TAPP/SVP/Presencial). E5: Catálogo estandarizado de estados y motivos por etapa (aprobado/rechazado/abandono/error/pendiente) para analítica. E6: Especificación de tracking/instrumentación (event schema, payload mínimo, fuentes, frecuencia, validaciones de calidad). E7: Implementación del pipeline de datos (ingesta → validación → modelo analítico → dataset de funnel + abandono + reconversión). E8: Dashboards integrados: conversión por etapa/canal, abandono por nodo, reconversión a sucursal, cohortes, tendencias + alertas operativas. E9: Validación de datos (reconciliación vs sistemas fuente, completitud, latencia, consistencia) + evidencias de prueba. E10: Reporte baseline (situación actual: 565.297 → 28.280 + niveles de abandono) y playbook de acciones de recuperación. E11: Plan de seguimiento post-mejoras (gobierno, cadencia, triggers para derivar/contactar). | L9: INI-07, INI-08, INI-12, INI-26, INI-27, INI-28 | M9: definición oficial de las 5 etapas y eventos, instrumentación de TAPP/SVP, data platform/pipeline, estándar de IDs para unir TAPP/SVP/Siebel, definición de abandono y catálogo de motivos (especialmente 'No' en sim/eval), y mecanismo de match con sucursal para reconversión; se apalanca en y es base de análisis para . Absorbe el alcance completo de la anterior | N9: Requiere definición oficial de las 5 etapas y eventos, instrumentación de TAPP/SVP, data platform/pipeline, estándar de IDs para unir TAPP/SVP/Siebel, definición de abandono y catálogo de motivos (especialmente 'No' en sim/eval), y mecanismo de match con sucursal para reconversión; depende de INI-12 (gobierno), se apalanca en INI-07 (omnicanalidad/retoma) y es base de análisis para INI-08. Absorbe el alcance completo de la anterior INI-09 (ex INI-10). 🔗 DEPENDENCIAS CRUZADAS (Func↔Téc): INI-26 (BigQuery para analytics); INI-27 (Observabilidad base); INI-28 (Trazabilidad E2E). | O9: Requiere definición oficial de las 5 etapas y eventos, instrumentación de TAPP/SVP, data platform/pipeline, estándar de IDs para unir TAPP/SVP/Siebel, definición de abandono y catálogo de motivos (especialmente 'No' en sim/eval), y mecanismo de match con sucursal para reconversión; depende de INI-12 (gobierno), se apalanca en INI-07 (omnicanalidad/retoma) y es base de análisis para INI-08. Absorbe el alcance completo de la anterior INI-09 (ex INI-10). | P9: PENDIENTE EN CASO DE PRIORIZACIÓN | Q9: Data/BI / Analytics (owner), TI Data/Plataforma, Canales Digitales (TAPP/SVP), Ger. Sucursal Presencial + Equipo Siebel (match reconversión), TI Integración (eventos/IDs), Operaciones, Ger. Comercial, Ger. Riesgo (para motivos/estados) | R9: Funcional | S9: FG-19 FG-31 | T9: 📊 Negocio | V9: Transversal (todo el flujo) | W9: Transversal | X9: FG-19/FG-31: Trazabilidad de funnel E2E, mide abandono por etapa | Y9: BigQuery / GCP Analytics | Z9: TAPP, Siebel, FICO | AA9: Datos y Analítica | AB9: Datos / BI | AC9: GCP | AD9: BigQuery, Looker/DataStudio, Dashboards | AE9: — | AG9: Sin cambios
A10: INI-11 | B10: Desacople Lógica de Negocio del Motor + Gobierno de Reglas | C10: Reglas de knockout y scoring están embebidas en FICO sin interfaz de negocio. Cambiar una regla toma semanas vía TI. Se necesita capa de parametrización donde Riesgo gestione reglas autónomamente. [Ampliación — Gobierno de Reglas] Definir el modelo de gobierno para la gestión de reglas desacopladas: responsables por tipo de regla (knockout, scoring, oferta), protocolo de solicitud/aprobación/despliegue de cambios, flujo de autorización (quién solicita, quién valida impacto, quién aprueba, quién ejecuta), ventanas de cambio permitidas, y trazabilidad de cada modificación con auditoría. | D10: Implementar una capa de parametrización/gestión de reglas (interfaz de negocio) que desacople las reglas de knockout y scoring hoy embebidas en FICO/motor técnico, permitiendo que Riesgo administre y publique cambios de reglas de forma autónoma, controlada y auditable, reduciendo el time-to-change de semanas a ciclos cortos sin depender de TI para cada ajuste. | E10: =SUMIF('Por actividad (2)'!A:A,'Iniciativas (2)'!A10,'Por actividad (2)'!N:N) -> 93206.278 | F10: Funcional/Negocio | G10: Transversal (Express + Normal + Sin oferta) | I10: B1: Reduce drásticamente el tiempo de cambio de reglas (de semanas a días/horas según gobernanza). B2: Aumenta la agilidad del negocio para ajustar apetito de riesgo, pricing y campañas. B3: Mejora la gobernanza y auditoría (versionado, aprobaciones, trazabilidad de qué regla aplicó). B4: Disminuye riesgo operativo por cambios “hardcodeados” y despliegues frecuentes de TI. B5: Habilita pruebas y simulación de cambios (impacto antes de publicar) y rollback seguro. B6: Facilita consistencia omnicanal al centralizar reglas consumidas por los flujos (INI-01/02/03/05/08). | J10: A1: Levantar reglas actuales en FICO/motor (knockouts, thresholds, segmentos) y definir qué se externaliza a la capa de reglas. A2: Definir el modelo de reglas (tipos de regla, prioridad, condiciones, acciones, motivos/códigos) y requerimientos no funcionales (latencia, disponibilidad). A3: Diseñar la interfaz de negocio: edición, validaciones, workflow de aprobación, versionado, comentarios, publicación por ambiente. A4: Diseñar el runtime: cómo el motor técnico consume reglas (API/config), caching, idempotencia, y compatibilidad con FICO. A5: Implementar simulador/sandbox y controles de despliegue (feature flags, canary, rollback). A6: Piloto: migrar un set acotado de reglas, medir tiempos de cambio, errores, performance y ajustar gobernanza. A7: Definir modelo de gobierno de reglas: asignar responsables por tipo de regla (knockout → Ger. Riesgo, scoring → Ger. Riesgo, oferta → Ger. Producto), definir protocolo de solicitud/aprobación/despliegue de cambios, ventanas de cambio permitidas y mecanismo de auditoría y trazabilidad de cada modificación. | K10: E1: Inventario de reglas actuales + decisión de externalización (qué queda en FICO vs qué pasa a capa negocio). E2: Modelo de reglas y estándar de motivos/códigos (estructura, prioridades, condiciones/acciones). E3: Diseño e implementación de la Interfaz de Reglas (UI) con workflow (creación, revisión, aprobación, publicación). E4: API/Contrato para consumo de reglas por el motor/orquestador (OpenAPI) + estrategia de caching y resiliencia. E5: Versionado y auditoría: trazas por decisión (rule-id, versión, variables usadas), bitácora de cambios y permisos. E6: Sandbox/Simulador de impacto (pruebas con histórico, comparativo antes/después, reportes). E7: Implementación de controles de despliegue (feature flags, canary, rollback) y guía operativa. E8: Plan y evidencias de pruebas (funcionales, seguridad, performance, regresión) + UAT con Riesgo. E9: Gobierno/RACI y manual de operación (roles, permisos, cadencia de cambios, checklist de publicación). | L10: INI-01, INI-12, INI-13, INI-18, INI-23, INI-33 | M10: seleccionar solución de reglas (BRMS/DMN o capa propia), IAM/roles, workflow de aprobación, versionado/auditoría/rollback y sandbox de simulación; y habilita agilidad/parametría para /02/03/05/08 y potencialmente umbrales/validaciones de | N10: Requiere seleccionar solución de reglas (BRMS/DMN o capa propia), IAM/roles, workflow de aprobación, versionado/auditoría/rollback y sandbox de simulación; depende de INI-12 y habilita agilidad/parametría para INI-01/02/03/05/08 y potencialmente umbrales/validaciones de INI-13 (ex INI-17). 🔗 DEPENDENCIAS CRUZADAS (Func↔Téc): INI-18 (FICO v7 para desacoplar); INI-33 (Parametrización reglas + IA); INI-23 (Jobs separados). | O10: Requiere seleccionar solución de reglas (BRMS/DMN o capa propia), IAM/roles, workflow de aprobación, versionado/auditoría/rollback y sandbox de simulación; depende de INI-12 y habilita agilidad/parametría para INI-01/02/03/05/08 y potencialmente umbrales/validaciones de INI-13 (ex INI-17). | P10: PENDIENTE EN CASO DE PRIORIZACIÓN | Q10: Ger. Riesgo (owner funcional de reglas), TI Arquitectura/Integración (owner técnico), Proveedor FICO/Ventiv, Seguridad/Ciber (roles/auditoría), Compliance, Data/BI (simulación/impacto) | R10: Funcional | S10: FG-29 FG-33 | T10: 🔴 Riesgo📊 Negocio | V10: Evaluación | W10: Evaluación | X10: FG-29/FG-33: Desacople reglas del motor FICO → interfaz parametrización | Y10: Motor FICO (DMPS/Blaze) | Z10: Blaze Advisor, OSB | AA10: Motor de Decisión | AB10: Lógica de Negocio | AC10: OCI Santiago / OKE | AD10: Blaze Advisor v7 (120+ reglas), DMPS | AE10: — | AF10: ✅ AMPLIADA: Se agrega gobierno de reglas (responsables, protocolo cambios, flujo autorización, auditoría). Prerrequisito de INI-33. | AG10: Ampliada
A11: INI-12 | B11: Gobierno Integral E2E del Proceso de Crédito (Blueprint + Owner + RACI + Cadencias) | C11: [Componente Funcional — ex INI-12] El flujo To-Be propuesto es el blueprint, pero hoy cada área tiene comprensión parcial y distinta del proceso. Se debe documentar, socializar y mantener como activo vivo con ownership asignado. [Componente Técnico-Operativo — ex INI-29] Designación de owner E2E del proceso de otorgamiento de crédito. Matriz RACI por componente y gerencia. Cadencias formales: daily operativo, semanal táctica, quincenal estratégica. Gobierno incremental en cada TO-BE. | D11: Documentar, socializar y establecer gobierno del Blueprint E2E del flujo de admisión (TO-BE) como un activo vivo, asegurando una comprensión única y alineada entre áreas (Negocio, Riesgo, TI, Operaciones y Canales: TAPP, SVP, Sucursal Presencial), con ownership, versionado y mecanismo de actualización continua. | E11: =SUMIF('Por actividad (2)'!A:A,'Iniciativas (2)'!A11,'Por actividad (2)'!N:N) -> 58565.022 | F11: Gobierno y Personas | G11: Transversal (todos los flujos) | I11: B1: Alineamiento transversal: reduce interpretaciones distintas del proceso y evita retrabajo. B2: Mejora la ejecución de iniciativas (INI-01 a INI-11) al tener una referencia única de flujo, decisiones y dependencias. B3: Facilita gestión del cambio: comunicación y capacitación más rápida y consistente por canal/área. B4: Reduce riesgos operativos y de compliance al clarificar controles, responsables y evidencias por etapa. B5: Habilita mejora continua con versionado: se puede comparar “as-is vs to-be” y medir impacto por release. | J11: A1: Consolidar el flujo TO-BE en un modelo único (E2E) con etapas, decisiones, variantes por tipo de cliente/canal. A2: Documentar RACI/ownership por etapa (quién define, ejecuta, aprueba cambios; puntos de control). A3: Definir estándares de documentación: BPMN, glosario, catálogos (estados/motivos), y definición de interfaces entre áreas/sistemas. A4: Realizar talleres de socialización/validación con stakeholders y cerrar acuerdos (Riesgo, Canales, Ops, TI, Legal/Compliance). A5: Publicar en repositorio corporativo con versionado (control de cambios, releases, calendario de revisiones). A6: Implementar mecanismo de mantenimiento: cadencia de actualización, comité de cambios y “definition of done” documental por iniciativa. A7: Definir cadencias operativas formales: daily operativo, semanal táctico, quincenal estratégico. Establecer Owner E2E del proceso de crédito con autoridad para resolver conflictos entre áreas. A8: Implementar modelo de gobierno incremental: medir madurez baseline (AS-IS) con scoring COBIT y definir metas por cada ciclo TO-BE. | K11: E1: Blueprint E2E (diagrama principal) del flujo de admisión TO-BE con variantes (Express/Normal/Sin oferta/NO OK; TAPP/SVP/Presencial). E2: Paquete de documentación por etapa (Generación de oferta, Simulación, Evaluación, Documentación, Curse): objetivos, entradas/salidas, controles. E3: RACI y ownership (dueño del proceso, dueños por etapa, aprobadores, operación). E4: Glosario y diccionario de términos (etapas, estados, “No”, motivos, IDs, SLA). E5: Mapa de integraciones e interfaces (sistemas involucrados, APIs, datos, SLAs, puntos de fallo). E6: Catálogo estándar de estados/motivos (para operación y analítica: INI-09/10). E7: Materiales de socialización: presentaciones, minutas, FAQs y capacitaciones por área/canal. E8: Repositorio publicado (Confluence/SharePoint/etc.) con control de versiones y plantilla estándar. E9: Modelo de gobierno y cadencia (comité, proceso de cambios, checklist y calendario de revisión). | M11: sponsor, dueños por etapa, repositorio y cadencia de actualización | N11: Requiere sponsor, dueños por etapa, repositorio y cadencia de actualización; no depende de otras INI y actúa como base/gobierno para el resto. 🔗 DEPENDENCIAS CRUZADAS (Func↔Téc): INI-29 (Gobierno E2E técnico — contraparte técnica). | O11: Requiere sponsor, dueños por etapa, repositorio y cadencia de actualización; no depende de otras INI y actúa como base/gobierno para el resto. | P11: PENDIENTE EN CASO DE PRIORIZACIÓN | Q11: PMO / Gestión de Procesos (owner), Ger. Comercial, Ger. Riesgo, Operaciones, TI Arquitectura, Canales (TAPP/SVP/Sucursal), Legal/Compliance | R11: Funcional + Técnica | S11: FG-35 | T11: Gobierno | V11: Transversal (Gobierno) | W11: Transversal | X11: FG-35: Gobierno del proceso E2E, no es una etapa específica | Y11: Gobierno / Proceso (no aplicativo) | Z11: Todos los sistemas | AA11: Gobierno y Operación | AB11: Gobierno | AC11: N/A (organizacional) | AD11: RACI, cadencias, owner E2E | AE11: — | AF11: ✅ FUSIÓN: Absorbe INI-29 (Owner+RACI+Cadencias). Ahora cubre blueprint funcional + modelo operativo gobierno. INI-29 eliminada. | AG11: Fusionada (absorbió INI-29)
A12: INI-13 | B12: Resiliencia Operativa | C12: Hoy si un componente falla (crítico o no) el flujo completo se detiene sin rutas alternativas. No existe clasificación de dependencias por criticidad, ni fallbacks definidos, ni monitoreo proactivo de la salud de componentes clave (como la Base de Aprobados y su batch nocturno). Esta iniciativa aborda: (1) resiliencia funcional con modos degradados y fallbacks por etapa/canal; y (2) sensor de salud de componentes críticos (Base de Aprobados, batch, campañas), para asegurar continuidad parcial controlada del servicio de crédito. | D12: Diseñar e implementar un marco de resiliencia operativa para el proceso de admisión de crédito que: (1) clasifique dependencias por criticidad; (2) defina modos degradados y fallbacks controlados por etapa, canal y tipo de cliente; (3) establezca lineamientos para mantener continuidad operativa ante contingencias, minimizando interrupciones totales; y (4) asegure el mantenimiento de controles de riesgo y compliance durante la operación degradada. | E12: =SUMIF('Por actividad (2)'!A:A,'Iniciativas (2)'!A12,'Por actividad (2)'!N:N) -> 142044.84 | F12: Técnico | G12: Transversal (todos los flujos) | I12: B1: Reduce caídas completas del onboarding cuando falla un componente no crítico (modos degradados). B2: Detección temprana de incidentes en componentes clave (Base de Aprobados, batch, campañas) antes de impacto masivo. B3: Mejora la conversión al evitar pérdidas por indisponibilidad parcial o fallas silenciosas. B4: Aumenta la continuidad operativa (TAPP, SVP, Sucursal) con rutas alternativas controladas. B5: Reduce pérdida de conversión por fallas silenciosas. B6: Reduce impacto en SLA/TAT al permitir avanzar o aparcar casos con reintentos automáticos. B7: Mantiene control y cumplimiento al definir qué fallbacks son permitidos y cuáles requieren derivación humana o stop. B9: Mejora observabilidad y gestión de incidentes. B10: Aumenta confiabilidad de campañas y canal banner al asegurar calidad y disponibilidad de datos. B11: Entrega trazabilidad para análisis de causa raíz. | J12: A1: Clasificar dependencias por criticidad (críticas / no críticas) por etapa. A2: Definir estrategias de fallback por falla: reintento, cola y reproceso, caché/último valor válido, bypass controlado, derivación humana o pausa con retoma. A3: Definir reglas de degradación permitida por tipo de cliente y canal. A4: Definir qué es validación y falla en componentes clave (Base de Aprobados, batch nocturno, campañas). A5: Definir métricas del sensor de salud: % fallas, volumen, frescura del batch, distribución por motivo, umbrales y ventanas de tiempo. A7: Implementar controles técnicos: timeouts, circuit breaker, colas, idempotencia, almacenamiento de estado para retoma. A8: Implementar sensor de salud de componentes críticos. A9: Implementar alertamiento operacional, rutas de escalamiento y runbooks por tipo de falla. A10: Implementar trazabilidad de eventos, motivos y métricas de modo degradado y sensor de salud. A11: Pruebas de resiliencia, simulación de fallas, calibración de umbrales y piloto controlado. | K12: E1: Matriz de dependencias y criticidad por etapa/canal. E2: Catálogo de modos degradados y fallbacks aprobados. E3: Reglas de continuidad vs stop. E4: Especificación del sensor de salud. E5: Definición de reglas de validación y catálogo de fallas/motivos. E7: Diseño técnico de resiliencia. E8: Implementación del motor de monitoreo/sensor. E9: Catálogo de motivos/códigos de fallas y fallback activado. E10: Implementación en orquestador/microservicios/canales. E11: Configuración de alertas y escalamiento + runbooks operativos. E12: Dashboard integrado de salud y resiliencia. E13: Plan y evidencias de pruebas de resiliencia + UAT. E14: Plan de operación. | L12: INI-06, INI-07, INI-09, INI-12, INI-24, INI-27, INI-31 | M12: clasificación de dependencias críticas/no críticas patrones de resiliencia (timeouts / circuit breaker / colas / retry) instrumentación de validación en FICO/Base Aprobados definición de umbrales y ventanas runbooks y aprobación de fallbacks por Riesgo absorbe el alcance del sensor de salud Base Aprobados | N12: Requiere clasificación de dependencias críticas/no críticas, patrones de resiliencia (timeouts/circuit breaker/colas/retry), instrumentación de validación en FICO/Base Aprobados (éxito/falla+motivo), definición de umbrales y ventanas, runbooks y aprobación de fallbacks por Riesgo; depende de INI-12 (gobierno), se apalanca en INI-07 (pausar/retomar), INI-06 (derivación a canales) y se mide con INI-09. Absorbe el alcance completo de la anterior INI-13 (ex INI-17) (sensor de salud Base Aprobados). Los flujos de excepción por deprecación son clave para los ciclos TO-BE 2 y 3 (migración OSB→Camel, Siebel→Salesforce). 🔗 DEPENDENCIAS CRUZADAS (Func↔Téc): INI-24 (Camel con circuit breaker); INI-27 (Observabilidad para detectar fallas); INI-31 (Runbooks técnicos). | O12: Requiere clasificación de dependencias críticas/no críticas, patrones de resiliencia (timeouts/circuit breaker/colas/retry), instrumentación de validación en FICO/Base Aprobados (éxito/falla+motivo), definición de umbrales y ventanas, runbooks y aprobación de fallbacks por Riesgo; depende de INI-12 (gobierno), se apalanca en INI-07 (pausar/retomar), INI-06 (derivación a canales) y se mide con INI-09. Absorbe el alcance completo de la anterior INI-13 (ex INI-17) (sensor de salud Base Aprobados). Los flujos de excepción por deprecación son clave para los ciclos TO-BE 2 y 3 (migración OSB→Camel, Siebel→Salesforce). | P12: PENDIENTE EN CASO DE PRIORIZACIÓN | Q12: TI Arquitectura/Plataforma Operaciones Sonda Canales Proveedor FICO/Ventiv Ger. Riesgo Ger. Comercial Data/BI | R12: Técnica | S12: Transversal | T12: Gobierno📊 Negocio | V12: Transversal (todo el flujo) | W12: Transversal | X12: Resiliencia operativa aplicable a todas las etapas | Y12: Gobierno / Proceso (no aplicativo) | Z12: Todos los sistemas | AA12: Gobierno y Operación | AB12: Gobierno | AC12: N/A (organizacional) | AD12: Resiliencia operativa, continuidad | AE12: — | AF12: 🟢 OK: Nombre confirmado. Delimita QUÉ hacer ante falla (reglas negocio). Complementa INI-30 (proveedores) e INI-31 (runbooks). | AG12: Sin cambios
